Workbook
Name StageNames: StageMap[Stage]
Name StatusNames: WorkStatuses[Status]

Sheet Dashboard
AA1: =COUNTIFS(Pursuits[Active],1) -> 0 | AB1: Active pursuits | AD1: =IF(AA7<1,0,MATCH(1,Pursuits[Deadline order],0)) -> 0 | AE1: =IF(AA9<1,0,MATCH(1,Actions[Dashboard order],0)) -> 0 | AF1: =IF(AA10<1,0,MATCH(1,Pursuits[Review order],0)) -> 0
B2: Opportunity pipeline | C2: Opportunity pipeline | D2: Opportunity pipeline | E2: Opportunity pipeline | F2: Opportunity pipeline | G2: Opportunity pipeline | H2: Opportunity pipeline | I2: Opportunity pipeline | J2: Opportunity pipeline | K2: Opportunity pipeline | L2: Opportunity pipeline | M2: Opportunity pipeline | N2: Opportunity pipeline | O2: Opportunity pipeline | P2: Opportunity pipeline | Q2: Opportunity pipeline | R2: Opportunity pipeline | T2: Logo here | U2: Logo here | V2: Logo here | W2: Logo here | X2: Logo here | AA2: =COUNT(Pursuits[Included value]) -> 0 | AB2: Estimates available | AD2: =IF(AA7<2,0,MATCH(2,Pursuits[Deadline order],0)) -> 0 | AE2: =IF(AA9<2,0,MATCH(2,Actions[Dashboard order],0)) -> 0 | AF2: =IF(AA10<2,0,MATCH(2,Pursuits[Review order],0)) -> 0
T3: As of | U3: As of | AA3: =COUNTIFS(Pursuits[Input check],"?*")+COUNTIFS(Actions[Needs attention],"?*")+COUNTIFS(Sources[Input check],"?*")+COUNTIFS(StageMap[Input check],"?*")+COUNTIFS(WorkStatuses[Input check],"?*") -> 0 | AB3: Input issues | AD3: =IF(AA7<3,0,MATCH(3,Pursuits[Deadline order],0)) -> 0 | AE3: =IF(AA9<3,0,MATCH(3,Actions[Dashboard order],0)) -> 0 | AF3: =IF(AA10<3,0,MATCH(3,Pursuits[Review order],0)) -> 0
N4: =IF(AA3>0,AA3&IF(AA3=1," row needs attention"," rows need attention")&"; see working tabs","") | AA4: =SUM(Pursuits[Included value]) -> 0 | AB4: Estimated value | AE4: =IF(AA9<4,0,MATCH(4,Actions[Dashboard order],0)) -> 0
AA5: =COUNT(Pursuits[Probable value]) -> 0 | AB5: Probabilities available | AE5: =IF(AA9<5,0,MATCH(5,Actions[Dashboard order],0)) -> 0
AA6: =SUM(Pursuits[Probable value]) -> 0 | AB6: Probable value
B7: Active pursuits | C7: Active pursuits | D7: Active pursuits | E7: Active pursuits | F7: Active pursuits | H7: Estimated value | I7: Estimated value | J7: Estimated value | K7: Estimated value | L7: Estimated value | N7: Responses due in 30 days | O7: Responses due in 30 days | P7: Responses due in 30 days | Q7: Responses due in 30 days | R7: Responses due in 30 days | T7: Overdue actions | U7: Overdue actions | V7: Overdue actions | W7: Overdue actions | X7: Overdue actions | AA7: =COUNT(Pursuits[Deadline order]) -> 0 | AB7: Responses in 30 days
B8: =IF(AA11>0,"Check stages",AA1) -> 0 | H8: =IF(AA11>0,"Check stages",IF(AA2=0,"—",AA4)) -> — | N8: =IF(AA11>0,"Check stages",IF(AND(ISNUMBER(Dashboard!$V$3),Dashboard!$V$3>=1,Dashboard!$V$3<DATE(2099,1,1)),AA7,"Set As of")) -> Set As of | T8: =IF(AA11>0,"Check stages",IF(AA12>0,"Check status",IF(AND(ISNUMBER(Dashboard!$V$3),Dashboard!$V$3>=1,Dashboard!$V$3<DATE(2099,1,1)),AA8,"Set As of"))) -> Set As of | AA8: =IF(AND(ISNUMBER(Dashboard!$V$3),Dashboard!$V$3>=1,Dashboard!$V$3<DATE(2099,1,1)),COUNTIFS(Actions[Active pursuit],1,Actions[Open action],1,Actions[Sort date],"<"&Dashboard!$V$3),"") | AB8: Overdue actions
B9: =IF(AA11>0,"Resolve the stage settings",IF(AA1=0,"Add pursuits on Pipeline","Across active stages")) -> Add pursuits on Pipeline | H9: =IF(AA11>0,"Resolve the stage settings",AA2&" of "&AA1&" valued") -> 0 of 0 valued | N9: =IF(AND(ISNUMBER(Dashboard!$V$3),Dashboard!$V$3>=1,Dashboard!$V$3<DATE(2099,1,1)),"Includes responses due today","Enter the review date above") -> Enter the review date above | T9: =IF(AND(ISNUMBER(Dashboard!$V$3),Dashboard!$V$3>=1,Dashboard!$V$3<DATE(2099,1,1)),"Incomplete actions on active pursuits","Enter the review date above") -> Enter the review date above | AA9: =COUNT(Actions[Dashboard order]) -> 0 | AB9: Open actions
H10: =IF(OR(AA11>0,AA5=0),"",TEXT(AA6,"$0.00,,")&"m probable; "&AA5&" of "&AA1) | AA10: =COUNT(Pursuits[Review order]) -> 0 | AB10: Pursuits to review
AA11: =COUNTIFS(Pursuits[Identity valid],1)-COUNT(Pursuits[Active]) -> 0 | AB11: Unresolved pursuit stages
B12: Pipeline by stage | C12: Pipeline by stage | D12: Pipeline by stage | E12: Pipeline by stage | F12: Pipeline by stage | G12: Pipeline by stage | H12: Pipeline by stage | I12: Pipeline by stage | J12: Pipeline by stage | K12: Pipeline by stage | L12: Pipeline by stage | M12: Pipeline by stage | N12: Pipeline by stage | O12: Pipeline by stage | Q12: Upcoming responses | R12: Upcoming responses | S12: Upcoming responses | T12: Upcoming responses | U12: Upcoming responses | V12: Upcoming responses | W12: Upcoming responses | X12: Upcoming responses | AA12: =COUNTIFS(WorkStatuses[Input check],"?*") -> 0 | AB12: Invalid status settings
Q13: =IF(AD1=0,"",HYPERLINK("#'Pipeline'!B"&(AD1+7),IF(AD1=0,"",INDEX(Pursuits[Opportunity],AD1)))) | V13: =IF(AD1=0,"",INDEX(Pursuits[Response due],AD1))
AA14: Stage | AB14: Pursuits
Q15: =IF(AD1=0,"",INDEX(Pursuits[Response type],AD1)&", "&INDEX(Pursuits[Response clock],AD1)) | AA15: =SUBSTITUTE('Source Data'!AD40," ",CHAR(10)) -> Identified | AB15: =COUNTIFS(Pursuits[Stage],'Source Data'!AD40,Pursuits[Identity valid],1) -> 0
Q16: =IF(AD2=0,"",HYPERLINK("#'Pipeline'!B"&(AD2+7),IF(AD2=0,"",INDEX(Pursuits[Opportunity],AD2)))) | V16: =IF(AD2=0,"",INDEX(Pursuits[Response due],AD2)) | AA16: =SUBSTITUTE('Source Data'!AD41," ",CHAR(10)) -> Qualifying | AB16: =COUNTIFS(Pursuits[Stage],'Source Data'!AD41,Pursuits[Identity valid],1) -> 0
AA17: =SUBSTITUTE('Source Data'!AD42," ",CHAR(10)) -> Pursuing | AB17: =COUNTIFS(Pursuits[Stage],'Source Data'!AD42,Pursuits[Identity valid],1) -> 0
Q18: =IF(AD2=0,"",INDEX(Pursuits[Response type],AD2)&", "&INDEX(Pursuits[Response clock],AD2)) | AA18: =SUBSTITUTE('Source Data'!AD43," ",CHAR(10)) -> Preparing response | AB18: =COUNTIFS(Pursuits[Stage],'Source Data'!AD43,Pursuits[Identity valid],1) -> 0
Q19: =IF(AD3=0,"",HYPERLINK("#'Pipeline'!B"&(AD3+7),IF(AD3=0,"",INDEX(Pursuits[Opportunity],AD3)))) | V19: =IF(AD3=0,"",INDEX(Pursuits[Response due],AD3)) | AA19: =SUBSTITUTE('Source Data'!AD44," ",CHAR(10)) -> Submitted | AB19: =COUNTIFS(Pursuits[Stage],'Source Data'!AD44,Pursuits[Identity valid],1) -> 0
AA20: =SUBSTITUTE('Source Data'!AD45," ",CHAR(10)) -> Won | AB20: =COUNTIFS(Pursuits[Stage],'Source Data'!AD45,Pursuits[Identity valid],1) -> 0
Q21: =IF(AD3=0,"",INDEX(Pursuits[Response type],AD3)&", "&INDEX(Pursuits[Response clock],AD3)) | AA21: =SUBSTITUTE('Source Data'!AD46," ",CHAR(10)) -> Lost | AB21: =COUNTIFS(Pursuits[Stage],'Source Data'!AD46,Pursuits[Identity valid],1) -> 0
Q22: =IF(AA7=0,IF(AND(ISNUMBER(Dashboard!$V$3),Dashboard!$V$3>=1,Dashboard!$V$3<DATE(2099,1,1)),"No responses due in this window","Set the As of date"),IF(AA7>3,"3 of "&AA7&" shown; see Pipeline","")) -> Set the As of date | AA22: =SUBSTITUTE('Source Data'!AD47," ",CHAR(10)) -> Abandoned | AB22: =COUNTIFS(Pursuits[Stage],'Source Data'!AD47,Pursuits[Identity valid],1) -> 0
B23: Actions needing attention | C23: Actions needing attention | D23: Actions needing attention | E23: Actions needing attention | F23: Actions needing attention | G23: Actions needing attention | H23: Actions needing attention | I23: Actions needing attention | J23: Actions needing attention | K23: Actions needing attention | L23: Actions needing attention | M23: Actions needing attention | N23: Actions needing attention | O23: Actions needing attention | Q23: Pursuits needing review | R23: Pursuits needing review | S23: Pursuits needing review | T23: Pursuits needing review | U23: Pursuits needing review | V23: Pursuits needing review | W23: Pursuits needing review | X23: Pursuits needing review
B24: Pursuit | C24: Pursuit | D24: Pursuit | E24: Action | F24: Action | G24: Action | H24: Action | I24: Action | J24: Action | K24: Due | L24: Due | M24: Status | N24: Status | O24: Status
B25: =IF(AE1=0,"",HYPERLINK("#'Actions'!D"&(AE1+7),IF(AE1=0,"",IF(INDEX(Actions[Pursuit],AE1)="","",INDEX(Actions[Pursuit],AE1))))) | E25: =IF(AE1=0,"",IF(INDEX(Actions[Action],AE1)="","",INDEX(Actions[Action],AE1))) | K25: =IF(AE1=0,"",IF(INDEX(Actions[Due date],AE1)="","",INDEX(Actions[Due date],AE1))) | M25: =IF(AE1=0,"",IF(INDEX(Actions[Status],AE1)="","",INDEX(Actions[Status],AE1))) | Q25: =IF(AF1=0,"",HYPERLINK("#'Pipeline'!I"&(AF1+7),IF(AF1=0,"",IF(INDEX(Pursuits[Opportunity],AF1)="","Unnamed pursuit",INDEX(Pursuits[Opportunity],AF1))&CHAR(10)&INDEX(Pursuits[Needs attention],AF1))))
B27: =IF(AE2=0,"",HYPERLINK("#'Actions'!D"&(AE2+7),IF(AE2=0,"",IF(INDEX(Actions[Pursuit],AE2)="","",INDEX(Actions[Pursuit],AE2))))) | E27: =IF(AE2=0,"",IF(INDEX(Actions[Action],AE2)="","",INDEX(Actions[Action],AE2))) | K27: =IF(AE2=0,"",IF(INDEX(Actions[Due date],AE2)="","",INDEX(Actions[Due date],AE2))) | M27: =IF(AE2=0,"",IF(INDEX(Actions[Status],AE2)="","",INDEX(Actions[Status],AE2)))
Q28: =IF(AF2=0,"",HYPERLINK("#'Pipeline'!I"&(AF2+7),IF(AF2=0,"",IF(INDEX(Pursuits[Opportunity],AF2)="","Unnamed pursuit",INDEX(Pursuits[Opportunity],AF2))&CHAR(10)&INDEX(Pursuits[Needs attention],AF2))))
B29: =IF(AE3=0,"",HYPERLINK("#'Actions'!D"&(AE3+7),IF(AE3=0,"",IF(INDEX(Actions[Pursuit],AE3)="","",INDEX(Actions[Pursuit],AE3))))) | E29: =IF(AE3=0,"",IF(INDEX(Actions[Action],AE3)="","",INDEX(Actions[Action],AE3))) | K29: =IF(AE3=0,"",IF(INDEX(Actions[Due date],AE3)="","",INDEX(Actions[Due date],AE3))) | M29: =IF(AE3=0,"",IF(INDEX(Actions[Status],AE3)="","",INDEX(Actions[Status],AE3)))
B31: =IF(AE4=0,"",HYPERLINK("#'Actions'!D"&(AE4+7),IF(AE4=0,"",IF(INDEX(Actions[Pursuit],AE4)="","",INDEX(Actions[Pursuit],AE4))))) | E31: =IF(AE4=0,"",IF(INDEX(Actions[Action],AE4)="","",INDEX(Actions[Action],AE4))) | K31: =IF(AE4=0,"",IF(INDEX(Actions[Due date],AE4)="","",INDEX(Actions[Due date],AE4))) | M31: =IF(AE4=0,"",IF(INDEX(Actions[Status],AE4)="","",INDEX(Actions[Status],AE4))) | Q31: =IF(AF3=0,"",HYPERLINK("#'Pipeline'!I"&(AF3+7),IF(AF3=0,"",IF(INDEX(Pursuits[Opportunity],AF3)="","Unnamed pursuit",INDEX(Pursuits[Opportunity],AF3))&CHAR(10)&INDEX(Pursuits[Needs attention],AF3))))
B33: =IF(AE5=0,"",HYPERLINK("#'Actions'!D"&(AE5+7),IF(AE5=0,"",IF(INDEX(Actions[Pursuit],AE5)="","",INDEX(Actions[Pursuit],AE5))))) | E33: =IF(AE5=0,"",IF(INDEX(Actions[Action],AE5)="","",INDEX(Actions[Action],AE5))) | K33: =IF(AE5=0,"",IF(INDEX(Actions[Due date],AE5)="","",INDEX(Actions[Due date],AE5))) | M33: =IF(AE5=0,"",IF(INDEX(Actions[Status],AE5)="","",INDEX(Actions[Status],AE5)))
Q34: =IF(AA10=0,"No pursuits need review",IF(AA10>3,"3 of "&AA10&" shown; see Pipeline","")) -> No pursuits need review
B35: =IF(AA9=0,"No open actions",IF(AA9>5,"5 of "&AA9&" shown; see Actions","")) -> No open actions
B36: Add company details, an As of date, pursuits and actions. Blue cells accept inputs. | C36: Add company details, an As of date, pursuits and actions. Blue cells accept inputs. | D36: Add company details, an As of date, pursuits and actions. Blue cells accept inputs. | E36: Add company details, an As of date, pursuits and actions. Blue cells accept inputs. | F36: Add company details, an As of date, pursuits and actions. Blue cells accept inputs. | G36: Add company details, an As of date, pursuits and actions. Blue cells accept inputs. | H36: Add company details, an As of date, pursuits and actions. Blue cells accept inputs. | I36: Add company details, an As of date, pursuits and actions. Blue cells accept inputs. | J36: Add company details, an As of date, pursuits and actions. Blue cells accept inputs. | K36: Add company details, an As of date, pursuits and actions. Blue cells accept inputs. | L36: Add company details, an As of date, pursuits and actions. Blue cells accept inputs. | M36: Add company details, an As of date, pursuits and actions. Blue cells accept inputs. | N36: Add company details, an As of date, pursuits and actions. Blue cells accept inputs. | O36: Add company details, an As of date, pursuits and actions. Blue cells accept inputs. | P36: Add company details, an As of date, pursuits and actions. Blue cells accept inputs. | Q36: Add company details, an As of date, pursuits and actions. Blue cells accept inputs. | R36: Add company details, an As of date, pursuits and actions. Blue cells accept inputs. | S36: Add company details, an As of date, pursuits and actions. Blue cells accept inputs. | T36: Add company details, an As of date, pursuits and actions. Blue cells accept inputs. | U36: Add company details, an As of date, pursuits and actions. Blue cells accept inputs. | V36: Add company details, an As of date, pursuits and actions. Blue cells accept inputs. | W36: Add company details, an As of date, pursuits and actions. Blue cells accept inputs. | X36: Add company details, an As of date, pursuits and actions. Blue cells accept inputs.
B37: Pipeline | C37: Pipeline | D37: Pipeline | E37: Pipeline | F37: Pipeline | H37: Actions | I37: Actions | J37: Actions | K37: Actions | L37: Actions | N37: Source Data | O37: Source Data | P37: Source Data | Q37: Source Data | R37: Source Data | T37: Settings | U37: Settings | V37: Settings | W37: Settings | X37: Settings

Sheet Pipeline
A2: Pipeline | B2: Pipeline
A4: As of | B4: =IF(Dashboard!$V$3="","",Dashboard!$V$3) | C4: Blue inputs; gray calculations | D4: Blue inputs; gray calculations | E4: Blue inputs; gray calculations | F4: Blue inputs; gray calculations
C5: Value: total company contract scope (USD) | D5: Value: total company contract scope (USD) | E5: Value: total company contract scope (USD) | F5: Value: total company contract scope (USD) | G5: Value: total company contract scope (USD) | H5: Value: total company contract scope (USD) | I5: Value: total company contract scope (USD)
A7: Pursuit ID | B7: Opportunity | C7: Buyer | D7: Stage | E7: Response due | F7: Next action | G7: Action due | H7: Estimated value | I7: Needs attention | J7: Response type | K7: Description | L7: Agency office | M7: Solicitation | N7: Acquisition route | O7: Location | P7: Release period | Q7: Award period | R7: Duration months | S7: Last reviewed | T7: Value basis | U7: Value period | V7: Probability of win | W7: Probable value | X7: Notes | Y7: Owner | Z7: GovTribe link | AA7: Related file | AB7: Source ID | AC7: Reviewed source version | AD7: Source row | AE7: Active | AF7: ID check | AG7: Value check | AH7: Included value | AI7: Deadline order | AJ7: Next action ID | AK7: Review order | AL7: Open actions | AM7: Undated actions | AN7: Source change | AO7: Review age | AP7: Input check | AQ7: Response clock | AR7: Review candidate | AS7: Identity valid
E8: =IF($AD8=0,"",IF(INDEX(Sources[Response date],$AD8)="","",INDEX(Sources[Response date],$AD8))) | F8: =IF($AJ8="","",INDEX(Actions[Action],MATCH($AJ8,Actions[Action ID],0))) | G8: =IF($AJ8="","",IF(INDEX(Actions[Due date],MATCH($AJ8,Actions[Action ID],0))="","",INDEX(Actions[Due date],MATCH($AJ8,Actions[Action ID],0)))) | I8: =IF($A8="",$AF8,_xlfn.TEXTJOIN(CHAR(10),TRUE(),$AP8,$AG8,IF(AND($AE8=1,AND(ISNUMBER(Dashboard!$V$3),Dashboard!$V$3>=1,Dashboard!$V$3<DATE(2099,1,1)),ISNUMBER($E8),$E8<Dashboard!$V$3),"Response date passed",""),IF(AND($AE8=1,$AL8=0),"No next action",""),IF(AND($AE8=1,$AM8>0),"Action needs a date",""),IF($AE8=1,$AN8,""),$AO8,IF($AD8=0,"",INDEX(Sources[Source issue],$AD8)))) | L8: =IF($AD8=0,"",IF(INDEX(Sources[Agency office],$AD8)="","",INDEX(Sources[Agency office],$AD8))) | M8: =IF($AD8=0,"",IF(INDEX(Sources[Solicitation],$AD8)="","",INDEX(Sources[Solicitation],$AD8))) | N8: =IF($AD8=0,"",IF(INDEX(Sources[Acquisition route],$AD8)="","",INDEX(Sources[Acquisition route],$AD8))) | O8: =IF($AD8=0,"",IF(INDEX(Sources[Location],$AD8)="","",INDEX(Sources[Location],$AD8))) | P8: =IF($AD8=0,"",IF(INDEX(Sources[Release period],$AD8)="","",INDEX(Sources[Release period],$AD8))) | Q8: =IF($AD8=0,"",IF(INDEX(Sources[Award period],$AD8)="","",INDEX(Sources[Award period],$AD8))) | W8: =IF(AND(ISNUMBER($AH8),ISNUMBER($V8),$V8>=0,$V8<=1),ROUND($AH8*$V8,2),"") | Z8: =IF($AD8=0,"",IF(INDEX(Sources[GovTribe URL],$AD8)="","",HYPERLINK(INDEX(Sources[GovTribe URL],$AD8),"Open GovTribe"))) | AD8: =IF($A8="",0,IF(AND($AB8<>"",COUNTIFS(Sources[Source ID],$AB8,Sources[Pursuit ID],$A8)=1,COUNTIFS(Sources[Source ID],$AB8)=1),MATCH($AB8,Sources[Source ID],0),0)) -> 0 | AE8: =IF($AS8=0,"",IF(COUNTIFS(StageMap[Stage],$D8)<>1,"",IF(INDEX(StageMap[Input check],MATCH($D8,StageMap[Stage],0))="",INDEX(StageMap[Active],MATCH($D8,StageMap[Stage],0)),""))) | AF8: =IF($A8="",IF(COUNTA(B8:D8,H8,J8:K8,R8:V8,X8:Y8,AA8:AC8)>0,"Missing pursuit ID",""),IF(COUNTIFS(Pursuits[Pursuit ID],$A8)>1,"Duplicate pursuit ID",IF($B8="","Add opportunity name",""))) | AG8: =IF($A8="","",IF($H8="","",IF(NOT(ISNUMBER($H8)),"Enter a numeric estimate",IF($H8<0,"Estimate cannot be negative",IF($T8<>"Total company contract value","Non-total value excluded",IF($U8="","Add value period","")))))) | AH8: =IF(AND($AE8=1,$AG8="",ISNUMBER($H8)),$H8,"") | AI8: =IF(AND($AE8=1,AND(ISNUMBER(Dashboard!$V$3),Dashboard!$V$3>=1,Dashboard!$V$3<DATE(2099,1,1)),ISNUMBER($E8),$E8>=1,$E8<DATE(2099,1,1),$E8>=Dashboard!$V$3,$E8<Dashboard!$V$3+30),COUNTIFS(Pursuits[Active],1,Pursuits[Response due],">="&Dashboard!$V$3,Pursuits[Response due],"<"&$E8)+COUNTIFS(Pursuits[Active],1,Pursuits[Response due],$E8,Pursuits[Pursuit ID],"<"&$A8)+1,"") | AJ8: =IF(OR($A8="",$AL8=0),"",INDEX(Actions[Action ID],MATCH($A8&"|1",Actions[Pursuit action key],0))) | AK8: =IF($AR8<>1,"",COUNTIFS(Pursuits[Review candidate],1,Pursuits[Pursuit ID],"<"&$A8)+COUNTIFS($A$8:$A8,$A8,$AR$8:$AR8,1)) | AL8: =IF($A8="","",COUNTIFS(Actions[Pursuit ID],$A8,Actions[Open action],1)) | AM8: =IF($A8="","",COUNTIFS(Actions[Pursuit ID],$A8,Actions[Open action],1,Actions[Sort date],DATE(9999,12,31))) | AN8: =IF($AD8=0,"",IF($AC8="","Source not reviewed",IF($AC8<>INDEX(Sources[Source updated],$AD8),"Source changed",""))) | AO8: =IF(OR($AE8<>1,NOT(AND(ISNUMBER(Dashboard!$V$3),Dashboard!$V$3>=1,Dashboard!$V$3<DATE(2099,1,1)))),"",IF($S8="","Not reviewed",IF(NOT(ISNUMBER($S8)),"Use a real review date",IF($S8>Dashboard!$V$3,"Review date is in future",IF(AND(ISNUMBER('Source Data'!$AE$36),'Source Data'!$AE$36>0),IF(Dashboard!$V$3-$S8>'Source Data'!$AE$36,"Review is overdue",""),"Set review interval"))))) | AP8: =IF($AF8<>"",$AF8,IF($A8="","",IF(COUNTIFS(StageMap[Stage],$D8)<>1,"Choose a valid stage",IF(NOT(ISNUMBER($AE8)),"Check stage settings",IF($AB8="","Add source ID",IF($AD8=0,"Source link needs review",IF(INDEX(Sources[Input check],$AD8)<>"",INDEX(Sources[Input check],$AD8),IF(AND($V8<>"",OR(NOT(ISNUMBER($V8)),$V8<0,$V8>1)),"Probability must be 0 to 100%",IF(AND($R8<>"",OR(NOT(ISNUMBER($R8)),$R8<0)),"Use valid duration months",""))))))))) | AQ8: =IF($AD8=0,"",IF(INDEX(Sources[Response time],$AD8)="","Time not confirmed",TEXT(INDEX(Sources[Response time],$AD8),"h:mm AM/PM")&" "&INDEX(Sources[Time zone],$AD8))) | AR8: =IF(AND($I8<>"",OR($AE8=1,$AP8<>"")),1,0) -> 0 | AS8: =IF(AND($A8<>"",$AF8=""),1,0) -> 0
E9: =IF($AD9=0,"",IF(INDEX(Sources[Response date],$AD9)="","",INDEX(Sources[Response date],$AD9))) | F9: =IF($AJ9="","",INDEX(Actions[Action],MATCH($AJ9,Actions[Action ID],0))) | G9: =IF($AJ9="","",IF(INDEX(Actions[Due date],MATCH($AJ9,Actions[Action ID],0))="","",INDEX(Actions[Due date],MATCH($AJ9,Actions[Action ID],0)))) | I9: =IF($A9="",$AF9,_xlfn.TEXTJOIN(CHAR(10),TRUE(),$AP9,$AG9,IF(AND($AE9=1,AND(ISNUMBER(Dashboard!$V$3),Dashboard!$V$3>=1,Dashboard!$V$3<DATE(2099,1,1)),ISNUMBER($E9),$E9<Dashboard!$V$3),"Response date passed",""),IF(AND($AE9=1,$AL9=0),"No next action",""),IF(AND($AE9=1,$AM9>0),"Action needs a date",""),IF($AE9=1,$AN9,""),$AO9,IF($AD9=0,"",INDEX(Sources[Source issue],$AD9)))) | L9: =IF($AD9=0,"",IF(INDEX(Sources[Agency office],$AD9)="","",INDEX(Sources[Agency office],$AD9))) | M9: =IF($AD9=0,"",IF(INDEX(Sources[Solicitation],$AD9)="","",INDEX(Sources[Solicitation],$AD9))) | N9: =IF($AD9=0,"",IF(INDEX(Sources[Acquisition route],$AD9)="","",INDEX(Sources[Acquisition route],$AD9))) | O9: =IF($AD9=0,"",IF(INDEX(Sources[Location],$AD9)="","",INDEX(Sources[Location],$AD9))) | P9: =IF($AD9=0,"",IF(INDEX(Sources[Release period],$AD9)="","",INDEX(Sources[Release period],$AD9))) | Q9: =IF($AD9=0,"",IF(INDEX(Sources[Award period],$AD9)="","",INDEX(Sources[Award period],$AD9))) | W9: =IF(AND(ISNUMBER($AH9),ISNUMBER($V9),$V9>=0,$V9<=1),ROUND($AH9*$V9,2),"") | Z9: =IF($AD9=0,"",IF(INDEX(Sources[GovTribe URL],$AD9)="","",HYPERLINK(INDEX(Sources[GovTribe URL],$AD9),"Open GovTribe"))) | AD9: =IF($A9="",0,IF(AND($AB9<>"",COUNTIFS(Sources[Source ID],$AB9,Sources[Pursuit ID],$A9)=1,COUNTIFS(Sources[Source ID],$AB9)=1),MATCH($AB9,Sources[Source ID],0),0)) -> 0 | AE9: =IF($AS9=0,"",IF(COUNTIFS(StageMap[Stage],$D9)<>1,"",IF(INDEX(StageMap[Input check],MATCH($D9,StageMap[Stage],0))="",INDEX(StageMap[Active],MATCH($D9,StageMap[Stage],0)),""))) | AF9: =IF($A9="",IF(COUNTA(B9:D9,H9,J9:K9,R9:V9,X9:Y9,AA9:AC9)>0,"Missing pursuit ID",""),IF(COUNTIFS(Pursuits[Pursuit ID],$A9)>1,"Duplicate pursuit ID",IF($B9="","Add opportunity name",""))) | AG9: =IF($A9="","",IF($H9="","",IF(NOT(ISNUMBER($H9)),"Enter a numeric estimate",IF($H9<0,"Estimate cannot be negative",IF($T9<>"Total company contract value","Non-total value excluded",IF($U9="","Add value period","")))))) | AH9: =IF(AND($AE9=1,$AG9="",ISNUMBER($H9)),$H9,"") | AI9: =IF(AND($AE9=1,AND(ISNUMBER(Dashboard!$V$3),Dashboard!$V$3>=1,Dashboard!$V$3<DATE(2099,1,1)),ISNUMBER($E9),$E9>=1,$E9<DATE(2099,1,1),$E9>=Dashboard!$V$3,$E9<Dashboard!$V$3+30),COUNTIFS(Pursuits[Active],1,Pursuits[Response due],">="&Dashboard!$V$3,Pursuits[Response due],"<"&$E9)+COUNTIFS(Pursuits[Active],1,Pursuits[Response due],$E9,Pursuits[Pursuit ID],"<"&$A9)+1,"") | AJ9: =IF(OR($A9="",$AL9=0),"",INDEX(Actions[Action ID],MATCH($A9&"|1",Actions[Pursuit action key],0))) | AK9: =IF($AR9<>1,"",COUNTIFS(Pursuits[Review candidate],1,Pursuits[Pursuit ID],"<"&$A9)+COUNTIFS($A$8:$A9,$A9,$AR$8:$AR9,1)) | AL9: =IF($A9="","",COUNTIFS(Actions[Pursuit ID],$A9,Actions[Open action],1)) | AM9: =IF($A9="","",COUNTIFS(Actions[Pursuit ID],$A9,Actions[Open action],1,Actions[Sort date],DATE(9999,12,31))) | AN9: =IF($AD9=0,"",IF($AC9="","Source not reviewed",IF($AC9<>INDEX(Sources[Source updated],$AD9),"Source changed",""))) | AO9: =IF(OR($AE9<>1,NOT(AND(ISNUMBER(Dashboard!$V$3),Dashboard!$V$3>=1,Dashboard!$V$3<DATE(2099,1,1)))),"",IF($S9="","Not reviewed",IF(NOT(ISNUMBER($S9)),"Use a real review date",IF($S9>Dashboard!$V$3,"Review date is in future",IF(AND(ISNUMBER('Source Data'!$AE$36),'Source Data'!$AE$36>0),IF(Dashboard!$V$3-$S9>'Source Data'!$AE$36,"Review is overdue",""),"Set review interval"))))) | AP9: =IF($AF9<>"",$AF9,IF($A9="","",IF(COUNTIFS(StageMap[Stage],$D9)<>1,"Choose a valid stage",IF(NOT(ISNUMBER($AE9)),"Check stage settings",IF($AB9="","Add source ID",IF($AD9=0,"Source link needs review",IF(INDEX(Sources[Input check],$AD9)<>"",INDEX(Sources[Input check],$AD9),IF(AND($V9<>"",OR(NOT(ISNUMBER($V9)),$V9<0,$V9>1)),"Probability must be 0 to 100%",IF(AND($R9<>"",OR(NOT(ISNUMBER($R9)),$R9<0)),"Use valid duration months",""))))))))) | AQ9: =IF($AD9=0,"",IF(INDEX(Sources[Response time],$AD9)="","Time not confirmed",TEXT(INDEX(Sources[Response time],$AD9),"h:mm AM/PM")&" "&INDEX(Sources[Time zone],$AD9))) | AR9: =IF(AND($I9<>"",OR($AE9=1,$AP9<>"")),1,0) -> 0 | AS9: =IF(AND($A9<>"",$AF9=""),1,0) -> 0
E10: =IF($AD10=0,"",IF(INDEX(Sources[Response date],$AD10)="","",INDEX(Sources[Response date],$AD10))) | F10: =IF($AJ10="","",INDEX(Actions[Action],MATCH($AJ10,Actions[Action ID],0))) | G10: =IF($AJ10="","",IF(INDEX(Actions[Due date],MATCH($AJ10,Actions[Action ID],0))="","",INDEX(Actions[Due date],MATCH($AJ10,Actions[Action ID],0)))) | I10: =IF($A10="",$AF10,_xlfn.TEXTJOIN(CHAR(10),TRUE(),$AP10,$AG10,IF(AND($AE10=1,AND(ISNUMBER(Dashboard!$V$3),Dashboard!$V$3>=1,Dashboard!$V$3<DATE(2099,1,1)),ISNUMBER($E10),$E10<Dashboard!$V$3),"Response date passed",""),IF(AND($AE10=1,$AL10=0),"No next action",""),IF(AND($AE10=1,$AM10>0),"Action needs a date",""),IF($AE10=1,$AN10,""),$AO10,IF($AD10=0,"",INDEX(Sources[Source issue],$AD10)))) | L10: =IF($AD10=0,"",IF(INDEX(Sources[Agency office],$AD10)="","",INDEX(Sources[Agency office],$AD10))) | M10: =IF($AD10=0,"",IF(INDEX(Sources[Solicitation],$AD10)="","",INDEX(Sources[Solicitation],$AD10))) | N10: =IF($AD10=0,"",IF(INDEX(Sources[Acquisition route],$AD10)="","",INDEX(Sources[Acquisition route],$AD10))) | O10: =IF($AD10=0,"",IF(INDEX(Sources[Location],$AD10)="","",INDEX(Sources[Location],$AD10))) | P10: =IF($AD10=0,"",IF(INDEX(Sources[Release period],$AD10)="","",INDEX(Sources[Release period],$AD10))) | Q10: =IF($AD10=0,"",IF(INDEX(Sources[Award period],$AD10)="","",INDEX(Sources[Award period],$AD10))) | W10: =IF(AND(ISNUMBER($AH10),ISNUMBER($V10),$V10>=0,$V10<=1),ROUND($AH10*$V10,2),"") | Z10: =IF($AD10=0,"",IF(INDEX(Sources[GovTribe URL],$AD10)="","",HYPERLINK(INDEX(Sources[GovTribe URL],$AD10),"Open GovTribe"))) | AD10: =IF($A10="",0,IF(AND($AB10<>"",COUNTIFS(Sources[Source ID],$AB10,Sources[Pursuit ID],$A10)=1,COUNTIFS(Sources[Source ID],$AB10)=1),MATCH($AB10,Sources[Source ID],0),0)) -> 0 | AE10: =IF($AS10=0,"",IF(COUNTIFS(StageMap[Stage],$D10)<>1,"",IF(INDEX(StageMap[Input check],MATCH($D10,StageMap[Stage],0))="",INDEX(StageMap[Active],MATCH($D10,StageMap[Stage],0)),""))) | AF10: =IF($A10="",IF(COUNTA(B10:D10,H10,J10:K10,R10:V10,X10:Y10,AA10:AC10)>0,"Missing pursuit ID",""),IF(COUNTIFS(Pursuits[Pursuit ID],$A10)>1,"Duplicate pursuit ID",IF($B10="","Add opportunity name",""))) | AG10: =IF($A10="","",IF($H10="","",IF(NOT(ISNUMBER($H10)),"Enter a numeric estimate",IF($H10<0,"Estimate cannot be negative",IF($T10<>"Total company contract value","Non-total value excluded",IF($U10="","Add value period","")))))) | AH10: =IF(AND($AE10=1,$AG10="",ISNUMBER($H10)),$H10,"") | AI10: =IF(AND($AE10=1,AND(ISNUMBER(Dashboard!$V$3),Dashboard!$V$3>=1,Dashboard!$V$3<DATE(2099,1,1)),ISNUMBER($E10),$E10>=1,$E10<DATE(2099,1,1),$E10>=Dashboard!$V$3,$E10<Dashboard!$V$3+30),COUNTIFS(Pursuits[Active],1,Pursuits[Response due],">="&Dashboard!$V$3,Pursuits[Response due],"<"&$E10)+COUNTIFS(Pursuits[Active],1,Pursuits[Response due],$E10,Pursuits[Pursuit ID],"<"&$A10)+1,"") | AJ10: =IF(OR($A10="",$AL10=0),"",INDEX(Actions[Action ID],MATCH($A10&"|1",Actions[Pursuit action key],0))) | AK10: =IF($AR10<>1,"",COUNTIFS(Pursuits[Review candidate],1,Pursuits[Pursuit ID],"<"&$A10)+COUNTIFS($A$8:$A10,$A10,$AR$8:$AR10,1)) | AL10: =IF($A10="","",COUNTIFS(Actions[Pursuit ID],$A10,Actions[Open action],1)) | AM10: =IF($A10="","",COUNTIFS(Actions[Pursuit ID],$A10,Actions[Open action],1,Actions[Sort date],DATE(9999,12,31))) | AN10: =IF($AD10=0,"",IF($AC10="","Source not reviewed",IF($AC10<>INDEX(Sources[Source updated],$AD10),"Source changed",""))) | AO10: =IF(OR($AE10<>1,NOT(AND(ISNUMBER(Dashboard!$V$3),Dashboard!$V$3>=1,Dashboard!$V$3<DATE(2099,1,1)))),"",IF($S10="","Not reviewed",IF(NOT(ISNUMBER($S10)),"Use a real review date",IF($S10>Dashboard!$V$3,"Review date is in future",IF(AND(ISNUMBER('Source Data'!$AE$36),'Source Data'!$AE$36>0),IF(Dashboard!$V$3-$S10>'Source Data'!$AE$36,"Review is overdue",""),"Set review interval"))))) | AP10: =IF($AF10<>"",$AF10,IF($A10="","",IF(COUNTIFS(StageMap[Stage],$D10)<>1,"Choose a valid stage",IF(NOT(ISNUMBER($AE10)),"Check stage settings",IF($AB10="","Add source ID",IF($AD10=0,"Source link needs review",IF(INDEX(Sources[Input check],$AD10)<>"",INDEX(Sources[Input check],$AD10),IF(AND($V10<>"",OR(NOT(ISNUMBER($V10)),$V10<0,$V10>1)),"Probability must be 0 to 100%",IF(AND($R10<>"",OR(NOT(ISNUMBER($R10)),$R10<0)),"Use valid duration months",""))))))))) | AQ10: =IF($AD10=0,"",IF(INDEX(Sources[Response time],$AD10)="","Time not confirmed",TEXT(INDEX(Sources[Response time],$AD10),"h:mm AM/PM")&" "&INDEX(Sources[Time zone],$AD10))) | AR10: =IF(AND($I10<>"",OR($AE10=1,$AP10<>"")),1,0) -> 0 | AS10: =IF(AND($A10<>"",$AF10=""),1,0) -> 0
E11: =IF($AD11=0,"",IF(INDEX(Sources[Response date],$AD11)="","",INDEX(Sources[Response date],$AD11))) | F11: =IF($AJ11="","",INDEX(Actions[Action],MATCH($AJ11,Actions[Action ID],0))) | G11: =IF($AJ11="","",IF(INDEX(Actions[Due date],MATCH($AJ11,Actions[Action ID],0))="","",INDEX(Actions[Due date],MATCH($AJ11,Actions[Action ID],0)))) | I11: =IF($A11="",$AF11,_xlfn.TEXTJOIN(CHAR(10),TRUE(),$AP11,$AG11,IF(AND($AE11=1,AND(ISNUMBER(Dashboard!$V$3),Dashboard!$V$3>=1,Dashboard!$V$3<DATE(2099,1,1)),ISNUMBER($E11),$E11<Dashboard!$V$3),"Response date passed",""),IF(AND($AE11=1,$AL11=0),"No next action",""),IF(AND($AE11=1,$AM11>0),"Action needs a date",""),IF($AE11=1,$AN11,""),$AO11,IF($AD11=0,"",INDEX(Sources[Source issue],$AD11)))) | L11: =IF($AD11=0,"",IF(INDEX(Sources[Agency office],$AD11)="","",INDEX(Sources[Agency office],$AD11))) | M11: =IF($AD11=0,"",IF(INDEX(Sources[Solicitation],$AD11)="","",INDEX(Sources[Solicitation],$AD11))) | N11: =IF($AD11=0,"",IF(INDEX(Sources[Acquisition route],$AD11)="","",INDEX(Sources[Acquisition route],$AD11))) | O11: =IF($AD11=0,"",IF(INDEX(Sources[Location],$AD11)="","",INDEX(Sources[Location],$AD11))) | P11: =IF($AD11=0,"",IF(INDEX(Sources[Release period],$AD11)="","",INDEX(Sources[Release period],$AD11))) | Q11: =IF($AD11=0,"",IF(INDEX(Sources[Award period],$AD11)="","",INDEX(Sources[Award period],$AD11))) | W11: =IF(AND(ISNUMBER($AH11),ISNUMBER($V11),$V11>=0,$V11<=1),ROUND($AH11*$V11,2),"") | Z11: =IF($AD11=0,"",IF(INDEX(Sources[GovTribe URL],$AD11)="","",HYPERLINK(INDEX(Sources[GovTribe URL],$AD11),"Open GovTribe"))) | AD11: =IF($A11="",0,IF(AND($AB11<>"",COUNTIFS(Sources[Source ID],$AB11,Sources[Pursuit ID],$A11)=1,COUNTIFS(Sources[Source ID],$AB11)=1),MATCH($AB11,Sources[Source ID],0),0)) -> 0 | AE11: =IF($AS11=0,"",IF(COUNTIFS(StageMap[Stage],$D11)<>1,"",IF(INDEX(StageMap[Input check],MATCH($D11,StageMap[Stage],0))="",INDEX(StageMap[Active],MATCH($D11,StageMap[Stage],0)),""))) | AF11: =IF($A11="",IF(COUNTA(B11:D11,H11,J11:K11,R11:V11,X11:Y11,AA11:AC11)>0,"Missing pursuit ID",""),IF(COUNTIFS(Pursuits[Pursuit ID],$A11)>1,"Duplicate pursuit ID",IF($B11="","Add opportunity name",""))) | AG11: =IF($A11="","",IF($H11="","",IF(NOT(ISNUMBER($H11)),"Enter a numeric estimate",IF($H11<0,"Estimate cannot be negative",IF($T11<>"Total company contract value","Non-total value excluded",IF($U11="","Add value period","")))))) | AH11: =IF(AND($AE11=1,$AG11="",ISNUMBER($H11)),$H11,"") | AI11: =IF(AND($AE11=1,AND(ISNUMBER(Dashboard!$V$3),Dashboard!$V$3>=1,Dashboard!$V$3<DATE(2099,1,1)),ISNUMBER($E11),$E11>=1,$E11<DATE(2099,1,1),$E11>=Dashboard!$V$3,$E11<Dashboard!$V$3+30),COUNTIFS(Pursuits[Active],1,Pursuits[Response due],">="&Dashboard!$V$3,Pursuits[Response due],"<"&$E11)+COUNTIFS(Pursuits[Active],1,Pursuits[Response due],$E11,Pursuits[Pursuit ID],"<"&$A11)+1,"") | AJ11: =IF(OR($A11="",$AL11=0),"",INDEX(Actions[Action ID],MATCH($A11&"|1",Actions[Pursuit action key],0))) | AK11: =IF($AR11<>1,"",COUNTIFS(Pursuits[Review candidate],1,Pursuits[Pursuit ID],"<"&$A11)+COUNTIFS($A$8:$A11,$A11,$AR$8:$AR11,1)) | AL11: =IF($A11="","",COUNTIFS(Actions[Pursuit ID],$A11,Actions[Open action],1)) | AM11: =IF($A11="","",COUNTIFS(Actions[Pursuit ID],$A11,Actions[Open action],1,Actions[Sort date],DATE(9999,12,31))) | AN11: =IF($AD11=0,"",IF($AC11="","Source not reviewed",IF($AC11<>INDEX(Sources[Source updated],$AD11),"Source changed",""))) | AO11: =IF(OR($AE11<>1,NOT(AND(ISNUMBER(Dashboard!$V$3),Dashboard!$V$3>=1,Dashboard!$V$3<DATE(2099,1,1)))),"",IF($S11="","Not reviewed",IF(NOT(ISNUMBER($S11)),"Use a real review date",IF($S11>Dashboard!$V$3,"Review date is in future",IF(AND(ISNUMBER('Source Data'!$AE$36),'Source Data'!$AE$36>0),IF(Dashboard!$V$3-$S11>'Source Data'!$AE$36,"Review is overdue",""),"Set review interval"))))) | AP11: =IF($AF11<>"",$AF11,IF($A11="","",IF(COUNTIFS(StageMap[Stage],$D11)<>1,"Choose a valid stage",IF(NOT(ISNUMBER($AE11)),"Check stage settings",IF($AB11="","Add source ID",IF($AD11=0,"Source link needs review",IF(INDEX(Sources[Input check],$AD11)<>"",INDEX(Sources[Input check],$AD11),IF(AND($V11<>"",OR(NOT(ISNUMBER($V11)),$V11<0,$V11>1)),"Probability must be 0 to 100%",IF(AND($R11<>"",OR(NOT(ISNUMBER($R11)),$R11<0)),"Use valid duration months",""))))))))) | AQ11: =IF($AD11=0,"",IF(INDEX(Sources[Response time],$AD11)="","Time not confirmed",TEXT(INDEX(Sources[Response time],$AD11),"h:mm AM/PM")&" "&INDEX(Sources[Time zone],$AD11))) | AR11: =IF(AND($I11<>"",OR($AE11=1,$AP11<>"")),1,0) -> 0 | AS11: =IF(AND($A11<>"",$AF11=""),1,0) -> 0
E12: =IF($AD12=0,"",IF(INDEX(Sources[Response date],$AD12)="","",INDEX(Sources[Response date],$AD12))) | F12: =IF($AJ12="","",INDEX(Actions[Action],MATCH($AJ12,Actions[Action ID],0))) | G12: =IF($AJ12="","",IF(INDEX(Actions[Due date],MATCH($AJ12,Actions[Action ID],0))="","",INDEX(Actions[Due date],MATCH($AJ12,Actions[Action ID],0)))) | I12: =IF($A12="",$AF12,_xlfn.TEXTJOIN(CHAR(10),TRUE(),$AP12,$AG12,IF(AND($AE12=1,AND(ISNUMBER(Dashboard!$V$3),Dashboard!$V$3>=1,Dashboard!$V$3<DATE(2099,1,1)),ISNUMBER($E12),$E12<Dashboard!$V$3),"Response date passed",""),IF(AND($AE12=1,$AL12=0),"No next action",""),IF(AND($AE12=1,$AM12>0),"Action needs a date",""),IF($AE12=1,$AN12,""),$AO12,IF($AD12=0,"",INDEX(Sources[Source issue],$AD12)))) | L12: =IF($AD12=0,"",IF(INDEX(Sources[Agency office],$AD12)="","",INDEX(Sources[Agency office],$AD12))) | M12: =IF($AD12=0,"",IF(INDEX(Sources[Solicitation],$AD12)="","",INDEX(Sources[Solicitation],$AD12))) | N12: =IF($AD12=0,"",IF(INDEX(Sources[Acquisition route],$AD12)="","",INDEX(Sources[Acquisition route],$AD12))) | O12: =IF($AD12=0,"",IF(INDEX(Sources[Location],$AD12)="","",INDEX(Sources[Location],$AD12))) | P12: =IF($AD12=0,"",IF(INDEX(Sources[Release period],$AD12)="","",INDEX(Sources[Release period],$AD12))) | Q12: =IF($AD12=0,"",IF(INDEX(Sources[Award period],$AD12)="","",INDEX(Sources[Award period],$AD12))) | W12: =IF(AND(ISNUMBER($AH12),ISNUMBER($V12),$V12>=0,$V12<=1),ROUND($AH12*$V12,2),"") | Z12: =IF($AD12=0,"",IF(INDEX(Sources[GovTribe URL],$AD12)="","",HYPERLINK(INDEX(Sources[GovTribe URL],$AD12),"Open GovTribe"))) | AD12: =IF($A12="",0,IF(AND($AB12<>"",COUNTIFS(Sources[Source ID],$AB12,Sources[Pursuit ID],$A12)=1,COUNTIFS(Sources[Source ID],$AB12)=1),MATCH($AB12,Sources[Source ID],0),0)) -> 0 | AE12: =IF($AS12=0,"",IF(COUNTIFS(StageMap[Stage],$D12)<>1,"",IF(INDEX(StageMap[Input check],MATCH($D12,StageMap[Stage],0))="",INDEX(StageMap[Active],MATCH($D12,StageMap[Stage],0)),""))) | AF12: =IF($A12="",IF(COUNTA(B12:D12,H12,J12:K12,R12:V12,X12:Y12,AA12:AC12)>0,"Missing pursuit ID",""),IF(COUNTIFS(Pursuits[Pursuit ID],$A12)>1,"Duplicate pursuit ID",IF($B12="","Add opportunity name",""))) | AG12: =IF($A12="","",IF($H12="","",IF(NOT(ISNUMBER($H12)),"Enter a numeric estimate",IF($H12<0,"Estimate cannot be negative",IF($T12<>"Total company contract value","Non-total value excluded",IF($U12="","Add value period","")))))) | AH12: =IF(AND($AE12=1,$AG12="",ISNUMBER($H12)),$H12,"") | AI12: =IF(AND($AE12=1,AND(ISNUMBER(Dashboard!$V$3),Dashboard!$V$3>=1,Dashboard!$V$3<DATE(2099,1,1)),ISNUMBER($E12),$E12>=1,$E12<DATE(2099,1,1),$E12>=Dashboard!$V$3,$E12<Dashboard!$V$3+30),COUNTIFS(Pursuits[Active],1,Pursuits[Response due],">="&Dashboard!$V$3,Pursuits[Response due],"<"&$E12)+COUNTIFS(Pursuits[Active],1,Pursuits[Response due],$E12,Pursuits[Pursuit ID],"<"&$A12)+1,"") | AJ12: =IF(OR($A12="",$AL12=0),"",INDEX(Actions[Action ID],MATCH($A12&"|1",Actions[Pursuit action key],0))) | AK12: =IF($AR12<>1,"",COUNTIFS(Pursuits[Review candidate],1,Pursuits[Pursuit ID],"<"&$A12)+COUNTIFS($A$8:$A12,$A12,$AR$8:$AR12,1)) | AL12: =IF($A12="","",COUNTIFS(Actions[Pursuit ID],$A12,Actions[Open action],1)) | AM12: =IF($A12="","",COUNTIFS(Actions[Pursuit ID],$A12,Actions[Open action],1,Actions[Sort date],DATE(9999,12,31))) | AN12: =IF($AD12=0,"",IF($AC12="","Source not reviewed",IF($AC12<>INDEX(Sources[Source updated],$AD12),"Source changed",""))) | AO12: =IF(OR($AE12<>1,NOT(AND(ISNUMBER(Dashboard!$V$3),Dashboard!$V$3>=1,Dashboard!$V$3<DATE(2099,1,1)))),"",IF($S12="","Not reviewed",IF(NOT(ISNUMBER($S12)),"Use a real review date",IF($S12>Dashboard!$V$3,"Review date is in future",IF(AND(ISNUMBER('Source Data'!$AE$36),'Source Data'!$AE$36>0),IF(Dashboard!$V$3-$S12>'Source Data'!$AE$36,"Review is overdue",""),"Set review interval"))))) | AP12: =IF($AF12<>"",$AF12,IF($A12="","",IF(COUNTIFS(StageMap[Stage],$D12)<>1,"Choose a valid stage",IF(NOT(ISNUMBER($AE12)),"Check stage settings",IF($AB12="","Add source ID",IF($AD12=0,"Source link needs review",IF(INDEX(Sources[Input check],$AD12)<>"",INDEX(Sources[Input check],$AD12),IF(AND($V12<>"",OR(NOT(ISNUMBER($V12)),$V12<0,$V12>1)),"Probability must be 0 to 100%",IF(AND($R12<>"",OR(NOT(ISNUMBER($R12)),$R12<0)),"Use valid duration months",""))))))))) | AQ12: =IF($AD12=0,"",IF(INDEX(Sources[Response time],$AD12)="","Time not confirmed",TEXT(INDEX(Sources[Response time],$AD12),"h:mm AM/PM")&" "&INDEX(Sources[Time zone],$AD12))) | AR12: =IF(AND($I12<>"",OR($AE12=1,$AP12<>"")),1,0) -> 0 | AS12: =IF(AND($A12<>"",$AF12=""),1,0) -> 0
E13: =IF($AD13=0,"",IF(INDEX(Sources[Response date],$AD13)="","",INDEX(Sources[Response date],$AD13))) | F13: =IF($AJ13="","",INDEX(Actions[Action],MATCH($AJ13,Actions[Action ID],0))) | G13: =IF($AJ13="","",IF(INDEX(Actions[Due date],MATCH($AJ13,Actions[Action ID],0))="","",INDEX(Actions[Due date],MATCH($AJ13,Actions[Action ID],0)))) | I13: =IF($A13="",$AF13,_xlfn.TEXTJOIN(CHAR(10),TRUE(),$AP13,$AG13,IF(AND($AE13=1,AND(ISNUMBER(Dashboard!$V$3),Dashboard!$V$3>=1,Dashboard!$V$3<DATE(2099,1,1)),ISNUMBER($E13),$E13<Dashboard!$V$3),"Response date passed",""),IF(AND($AE13=1,$AL13=0),"No next action",""),IF(AND($AE13=1,$AM13>0),"Action needs a date",""),IF($AE13=1,$AN13,""),$AO13,IF($AD13=0,"",INDEX(Sources[Source issue],$AD13)))) | L13: =IF($AD13=0,"",IF(INDEX(Sources[Agency office],$AD13)="","",INDEX(Sources[Agency office],$AD13))) | M13: =IF($AD13=0,"",IF(INDEX(Sources[Solicitation],$AD13)="","",INDEX(Sources[Solicitation],$AD13))) | N13: =IF($AD13=0,"",IF(INDEX(Sources[Acquisition route],$AD13)="","",INDEX(Sources[Acquisition route],$AD13))) | O13: =IF($AD13=0,"",IF(INDEX(Sources[Location],$AD13)="","",INDEX(Sources[Location],$AD13))) | P13: =IF($AD13=0,"",IF(INDEX(Sources[Release period],$AD13)="","",INDEX(Sources[Release period],$AD13))) | Q13: =IF($AD13=0,"",IF(INDEX(Sources[Award period],$AD13)="","",INDEX(Sources[Award period],$AD13))) | W13: =IF(AND(ISNUMBER($AH13),ISNUMBER($V13),$V13>=0,$V13<=1),ROUND($AH13*$V13,2),"") | Z13: =IF($AD13=0,"",IF(INDEX(Sources[GovTribe URL],$AD13)="","",HYPERLINK(INDEX(Sources[GovTribe URL],$AD13),"Open GovTribe"))) | AD13: =IF($A13="",0,IF(AND($AB13<>"",COUNTIFS(Sources[Source ID],$AB13,Sources[Pursuit ID],$A13)=1,COUNTIFS(Sources[Source ID],$AB13)=1),MATCH($AB13,Sources[Source ID],0),0)) -> 0 | AE13: =IF($AS13=0,"",IF(COUNTIFS(StageMap[Stage],$D13)<>1,"",IF(INDEX(StageMap[Input check],MATCH($D13,StageMap[Stage],0))="",INDEX(StageMap[Active],MATCH($D13,StageMap[Stage],0)),""))) | AF13: =IF($A13="",IF(COUNTA(B13:D13,H13,J13:K13,R13:V13,X13:Y13,AA13:AC13)>0,"Missing pursuit ID",""),IF(COUNTIFS(Pursuits[Pursuit ID],$A13)>1,"Duplicate pursuit ID",IF($B13="","Add opportunity name",""))) | AG13: =IF($A13="","",IF($H13="","",IF(NOT(ISNUMBER($H13)),"Enter a numeric estimate",IF($H13<0,"Estimate cannot be negative",IF($T13<>"Total company contract value","Non-total value excluded",IF($U13="","Add value period","")))))) | AH13: =IF(AND($AE13=1,$AG13="",ISNUMBER($H13)),$H13,"") | AI13: =IF(AND($AE13=1,AND(ISNUMBER(Dashboard!$V$3),Dashboard!$V$3>=1,Dashboard!$V$3<DATE(2099,1,1)),ISNUMBER($E13),$E13>=1,$E13<DATE(2099,1,1),$E13>=Dashboard!$V$3,$E13<Dashboard!$V$3+30),COUNTIFS(Pursuits[Active],1,Pursuits[Response due],">="&Dashboard!$V$3,Pursuits[Response due],"<"&$E13)+COUNTIFS(Pursuits[Active],1,Pursuits[Response due],$E13,Pursuits[Pursuit ID],"<"&$A13)+1,"") | AJ13: =IF(OR($A13="",$AL13=0),"",INDEX(Actions[Action ID],MATCH($A13&"|1",Actions[Pursuit action key],0))) | AK13: =IF($AR13<>1,"",COUNTIFS(Pursuits[Review candidate],1,Pursuits[Pursuit ID],"<"&$A13)+COUNTIFS($A$8:$A13,$A13,$AR$8:$AR13,1)) | AL13: =IF($A13="","",COUNTIFS(Actions[Pursuit ID],$A13,Actions[Open action],1)) | AM13: =IF($A13="","",COUNTIFS(Actions[Pursuit ID],$A13,Actions[Open action],1,Actions[Sort date],DATE(9999,12,31))) | AN13: =IF($AD13=0,"",IF($AC13="","Source not reviewed",IF($AC13<>INDEX(Sources[Source updated],$AD13),"Source changed",""))) | AO13: =IF(OR($AE13<>1,NOT(AND(ISNUMBER(Dashboard!$V$3),Dashboard!$V$3>=1,Dashboard!$V$3<DATE(2099,1,1)))),"",IF($S13="","Not reviewed",IF(NOT(ISNUMBER($S13)),"Use a real review date",IF($S13>Dashboard!$V$3,"Review date is in future",IF(AND(ISNUMBER('Source Data'!$AE$36),'Source Data'!$AE$36>0),IF(Dashboard!$V$3-$S13>'Source Data'!$AE$36,"Review is overdue",""),"Set review interval"))))) | AP13: =IF($AF13<>"",$AF13,IF($A13="","",IF(COUNTIFS(StageMap[Stage],$D13)<>1,"Choose a valid stage",IF(NOT(ISNUMBER($AE13)),"Check stage settings",IF($AB13="","Add source ID",IF($AD13=0,"Source link needs review",IF(INDEX(Sources[Input check],$AD13)<>"",INDEX(Sources[Input check],$AD13),IF(AND($V13<>"",OR(NOT(ISNUMBER($V13)),$V13<0,$V13>1)),"Probability must be 0 to 100%",IF(AND($R13<>"",OR(NOT(ISNUMBER($R13)),$R13<0)),"Use valid duration months",""))))))))) | AQ13: =IF($AD13=0,"",IF(INDEX(Sources[Response time],$AD13)="","Time not confirmed",TEXT(INDEX(Sources[Response time],$AD13),"h:mm AM/PM")&" "&INDEX(Sources[Time zone],$AD13))) | AR13: =IF(AND($I13<>"",OR($AE13=1,$AP13<>"")),1,0) -> 0 | AS13: =IF(AND($A13<>"",$AF13=""),1,0) -> 0
E14: =IF($AD14=0,"",IF(INDEX(Sources[Response date],$AD14)="","",INDEX(Sources[Response date],$AD14))) | F14: =IF($AJ14="","",INDEX(Actions[Action],MATCH($AJ14,Actions[Action ID],0))) | G14: =IF($AJ14="","",IF(INDEX(Actions[Due date],MATCH($AJ14,Actions[Action ID],0))="","",INDEX(Actions[Due date],MATCH($AJ14,Actions[Action ID],0)))) | I14: =IF($A14="",$AF14,_xlfn.TEXTJOIN(CHAR(10),TRUE(),$AP14,$AG14,IF(AND($AE14=1,AND(ISNUMBER(Dashboard!$V$3),Dashboard!$V$3>=1,Dashboard!$V$3<DATE(2099,1,1)),ISNUMBER($E14),$E14<Dashboard!$V$3),"Response date passed",""),IF(AND($AE14=1,$AL14=0),"No next action",""),IF(AND($AE14=1,$AM14>0),"Action needs a date",""),IF($AE14=1,$AN14,""),$AO14,IF($AD14=0,"",INDEX(Sources[Source issue],$AD14)))) | L14: =IF($AD14=0,"",IF(INDEX(Sources[Agency office],$AD14)="","",INDEX(Sources[Agency office],$AD14))) | M14: =IF($AD14=0,"",IF(INDEX(Sources[Solicitation],$AD14)="","",INDEX(Sources[Solicitation],$AD14))) | N14: =IF($AD14=0,"",IF(INDEX(Sources[Acquisition route],$AD14)="","",INDEX(Sources[Acquisition route],$AD14))) | O14: =IF($AD14=0,"",IF(INDEX(Sources[Location],$AD14)="","",INDEX(Sources[Location],$AD14))) | P14: =IF($AD14=0,"",IF(INDEX(Sources[Release period],$AD14)="","",INDEX(Sources[Release period],$AD14))) | Q14: =IF($AD14=0,"",IF(INDEX(Sources[Award period],$AD14)="","",INDEX(Sources[Award period],$AD14))) | W14: =IF(AND(ISNUMBER($AH14),ISNUMBER($V14),$V14>=0,$V14<=1),ROUND($AH14*$V14,2),"") | Z14: =IF($AD14=0,"",IF(INDEX(Sources[GovTribe URL],$AD14)="","",HYPERLINK(INDEX(Sources[GovTribe URL],$AD14),"Open GovTribe"))) | AD14: =IF($A14="",0,IF(AND($AB14<>"",COUNTIFS(Sources[Source ID],$AB14,Sources[Pursuit ID],$A14)=1,COUNTIFS(Sources[Source ID],$AB14)=1),MATCH($AB14,Sources[Source ID],0),0)) -> 0 | AE14: =IF($AS14=0,"",IF(COUNTIFS(StageMap[Stage],$D14)<>1,"",IF(INDEX(StageMap[Input check],MATCH($D14,StageMap[Stage],0))="",INDEX(StageMap[Active],MATCH($D14,StageMap[Stage],0)),""))) | AF14: =IF($A14="",IF(COUNTA(B14:D14,H14,J14:K14,R14:V14,X14:Y14,AA14:AC14)>0,"Missing pursuit ID",""),IF(COUNTIFS(Pursuits[Pursuit ID],$A14)>1,"Duplicate pursuit ID",IF($B14="","Add opportunity name",""))) | AG14: =IF($A14="","",IF($H14="","",IF(NOT(ISNUMBER($H14)),"Enter a numeric estimate",IF($H14<0,"Estimate cannot be negative",IF($T14<>"Total company contract value","Non-total value excluded",IF($U14="","Add value period","")))))) | AH14: =IF(AND($AE14=1,$AG14="",ISNUMBER($H14)),$H14,"") | AI14: =IF(AND($AE14=1,AND(ISNUMBER(Dashboard!$V$3),Dashboard!$V$3>=1,Dashboard!$V$3<DATE(2099,1,1)),ISNUMBER($E14),$E14>=1,$E14<DATE(2099,1,1),$E14>=Dashboard!$V$3,$E14<Dashboard!$V$3+30),COUNTIFS(Pursuits[Active],1,Pursuits[Response due],">="&Dashboard!$V$3,Pursuits[Response due],"<"&$E14)+COUNTIFS(Pursuits[Active],1,Pursuits[Response due],$E14,Pursuits[Pursuit ID],"<"&$A14)+1,"") | AJ14: =IF(OR($A14="",$AL14=0),"",INDEX(Actions[Action ID],MATCH($A14&"|1",Actions[Pursuit action key],0))) | AK14: =IF($AR14<>1,"",COUNTIFS(Pursuits[Review candidate],1,Pursuits[Pursuit ID],"<"&$A14)+COUNTIFS($A$8:$A14,$A14,$AR$8:$AR14,1)) | AL14: =IF($A14="","",COUNTIFS(Actions[Pursuit ID],$A14,Actions[Open action],1)) | AM14: =IF($A14="","",COUNTIFS(Actions[Pursuit ID],$A14,Actions[Open action],1,Actions[Sort date],DATE(9999,12,31))) | AN14: =IF($AD14=0,"",IF($AC14="","Source not reviewed",IF($AC14<>INDEX(Sources[Source updated],$AD14),"Source changed",""))) | AO14: =IF(OR($AE14<>1,NOT(AND(ISNUMBER(Dashboard!$V$3),Dashboard!$V$3>=1,Dashboard!$V$3<DATE(2099,1,1)))),"",IF($S14="","Not reviewed",IF(NOT(ISNUMBER($S14)),"Use a real review date",IF($S14>Dashboard!$V$3,"Review date is in future",IF(AND(ISNUMBER('Source Data'!$AE$36),'Source Data'!$AE$36>0),IF(Dashboard!$V$3-$S14>'Source Data'!$AE$36,"Review is overdue",""),"Set review interval"))))) | AP14: =IF($AF14<>"",$AF14,IF($A14="","",IF(COUNTIFS(StageMap[Stage],$D14)<>1,"Choose a valid stage",IF(NOT(ISNUMBER($AE14)),"Check stage settings",IF($AB14="","Add source ID",IF($AD14=0,"Source link needs review",IF(INDEX(Sources[Input check],$AD14)<>"",INDEX(Sources[Input check],$AD14),IF(AND($V14<>"",OR(NOT(ISNUMBER($V14)),$V14<0,$V14>1)),"Probability must be 0 to 100%",IF(AND($R14<>"",OR(NOT(ISNUMBER($R14)),$R14<0)),"Use valid duration months",""))))))))) | AQ14: =IF($AD14=0,"",IF(INDEX(Sources[Response time],$AD14)="","Time not confirmed",TEXT(INDEX(Sources[Response time],$AD14),"h:mm AM/PM")&" "&INDEX(Sources[Time zone],$AD14))) | AR14: =IF(AND($I14<>"",OR($AE14=1,$AP14<>"")),1,0) -> 0 | AS14: =IF(AND($A14<>"",$AF14=""),1,0) -> 0
E15: =IF($AD15=0,"",IF(INDEX(Sources[Response date],$AD15)="","",INDEX(Sources[Response date],$AD15))) | F15: =IF($AJ15="","",INDEX(Actions[Action],MATCH($AJ15,Actions[Action ID],0))) | G15: =IF($AJ15="","",IF(INDEX(Actions[Due date],MATCH($AJ15,Actions[Action ID],0))="","",INDEX(Actions[Due date],MATCH($AJ15,Actions[Action ID],0)))) | I15: =IF($A15="",$AF15,_xlfn.TEXTJOIN(CHAR(10),TRUE(),$AP15,$AG15,IF(AND($AE15=1,AND(ISNUMBER(Dashboard!$V$3),Dashboard!$V$3>=1,Dashboard!$V$3<DATE(2099,1,1)),ISNUMBER($E15),$E15<Dashboard!$V$3),"Response date passed",""),IF(AND($AE15=1,$AL15=0),"No next action",""),IF(AND($AE15=1,$AM15>0),"Action needs a date",""),IF($AE15=1,$AN15,""),$AO15,IF($AD15=0,"",INDEX(Sources[Source issue],$AD15)))) | L15: =IF($AD15=0,"",IF(INDEX(Sources[Agency office],$AD15)="","",INDEX(Sources[Agency office],$AD15))) | M15: =IF($AD15=0,"",IF(INDEX(Sources[Solicitation],$AD15)="","",INDEX(Sources[Solicitation],$AD15))) | N15: =IF($AD15=0,"",IF(INDEX(Sources[Acquisition route],$AD15)="","",INDEX(Sources[Acquisition route],$AD15))) | O15: =IF($AD15=0,"",IF(INDEX(Sources[Location],$AD15)="","",INDEX(Sources[Location],$AD15))) | P15: =IF($AD15=0,"",IF(INDEX(Sources[Release period],$AD15)="","",INDEX(Sources[Release period],$AD15))) | Q15: =IF($AD15=0,"",IF(INDEX(Sources[Award period],$AD15)="","",INDEX(Sources[Award period],$AD15))) | W15: =IF(AND(ISNUMBER($AH15),ISNUMBER($V15),$V15>=0,$V15<=1),ROUND($AH15*$V15,2),"") | Z15: =IF($AD15=0,"",IF(INDEX(Sources[GovTribe URL],$AD15)="","",HYPERLINK(INDEX(Sources[GovTribe URL],$AD15),"Open GovTribe"))) | AD15: =IF($A15="",0,IF(AND($AB15<>"",COUNTIFS(Sources[Source ID],$AB15,Sources[Pursuit ID],$A15)=1,COUNTIFS(Sources[Source ID],$AB15)=1),MATCH($AB15,Sources[Source ID],0),0)) -> 0 | AE15: =IF($AS15=0,"",IF(COUNTIFS(StageMap[Stage],$D15)<>1,"",IF(INDEX(StageMap[Input check],MATCH($D15,StageMap[Stage],0))="",INDEX(StageMap[Active],MATCH($D15,StageMap[Stage],0)),""))) | AF15: =IF($A15="",IF(COUNTA(B15:D15,H15,J15:K15,R15:V15,X15:Y15,AA15:AC15)>0,"Missing pursuit ID",""),IF(COUNTIFS(Pursuits[Pursuit ID],$A15)>1,"Duplicate pursuit ID",IF($B15="","Add opportunity name",""))) | AG15: =IF($A15="","",IF($H15="","",IF(NOT(ISNUMBER($H15)),"Enter a numeric estimate",IF($H15<0,"Estimate cannot be negative",IF($T15<>"Total company contract value","Non-total value excluded",IF($U15="","Add value period","")))))) | AH15: =IF(AND($AE15=1,$AG15="",ISNUMBER($H15)),$H15,"") | AI15: =IF(AND($AE15=1,AND(ISNUMBER(Dashboard!$V$3),Dashboard!$V$3>=1,Dashboard!$V$3<DATE(2099,1,1)),ISNUMBER($E15),$E15>=1,$E15<DATE(2099,1,1),$E15>=Dashboard!$V$3,$E15<Dashboard!$V$3+30),COUNTIFS(Pursuits[Active],1,Pursuits[Response due],">="&Dashboard!$V$3,Pursuits[Response due],"<"&$E15)+COUNTIFS(Pursuits[Active],1,Pursuits[Response due],$E15,Pursuits[Pursuit ID],"<"&$A15)+1,"") | AJ15: =IF(OR($A15="",$AL15=0),"",INDEX(Actions[Action ID],MATCH($A15&"|1",Actions[Pursuit action key],0))) | AK15: =IF($AR15<>1,"",COUNTIFS(Pursuits[Review candidate],1,Pursuits[Pursuit ID],"<"&$A15)+COUNTIFS($A$8:$A15,$A15,$AR$8:$AR15,1)) | AL15: =IF($A15="","",COUNTIFS(Actions[Pursuit ID],$A15,Actions[Open action],1)) | AM15: =IF($A15="","",COUNTIFS(Actions[Pursuit ID],$A15,Actions[Open action],1,Actions[Sort date],DATE(9999,12,31))) | AN15: =IF($AD15=0,"",IF($AC15="","Source not reviewed",IF($AC15<>INDEX(Sources[Source updated],$AD15),"Source changed",""))) | AO15: =IF(OR($AE15<>1,NOT(AND(ISNUMBER(Dashboard!$V$3),Dashboard!$V$3>=1,Dashboard!$V$3<DATE(2099,1,1)))),"",IF($S15="","Not reviewed",IF(NOT(ISNUMBER($S15)),"Use a real review date",IF($S15>Dashboard!$V$3,"Review date is in future",IF(AND(ISNUMBER('Source Data'!$AE$36),'Source Data'!$AE$36>0),IF(Dashboard!$V$3-$S15>'Source Data'!$AE$36,"Review is overdue",""),"Set review interval"))))) | AP15: =IF($AF15<>"",$AF15,IF($A15="","",IF(COUNTIFS(StageMap[Stage],$D15)<>1,"Choose a valid stage",IF(NOT(ISNUMBER($AE15)),"Check stage settings",IF($AB15="","Add source ID",IF($AD15=0,"Source link needs review",IF(INDEX(Sources[Input check],$AD15)<>"",INDEX(Sources[Input check],$AD15),IF(AND($V15<>"",OR(NOT(ISNUMBER($V15)),$V15<0,$V15>1)),"Probability must be 0 to 100%",IF(AND($R15<>"",OR(NOT(ISNUMBER($R15)),$R15<0)),"Use valid duration months",""))))))))) | AQ15: =IF($AD15=0,"",IF(INDEX(Sources[Response time],$AD15)="","Time not confirmed",TEXT(INDEX(Sources[Response time],$AD15),"h:mm AM/PM")&" "&INDEX(Sources[Time zone],$AD15))) | AR15: =IF(AND($I15<>"",OR($AE15=1,$AP15<>"")),1,0) -> 0 | AS15: =IF(AND($A15<>"",$AF15=""),1,0) -> 0
E16: =IF($AD16=0,"",IF(INDEX(Sources[Response date],$AD16)="","",INDEX(Sources[Response date],$AD16))) | F16: =IF($AJ16="","",INDEX(Actions[Action],MATCH($AJ16,Actions[Action ID],0))) | G16: =IF($AJ16="","",IF(INDEX(Actions[Due date],MATCH($AJ16,Actions[Action ID],0))="","",INDEX(Actions[Due date],MATCH($AJ16,Actions[Action ID],0)))) | I16: =IF($A16="",$AF16,_xlfn.TEXTJOIN(CHAR(10),TRUE(),$AP16,$AG16,IF(AND($AE16=1,AND(ISNUMBER(Dashboard!$V$3),Dashboard!$V$3>=1,Dashboard!$V$3<DATE(2099,1,1)),ISNUMBER($E16),$E16<Dashboard!$V$3),"Response date passed",""),IF(AND($AE16=1,$AL16=0),"No next action",""),IF(AND($AE16=1,$AM16>0),"Action needs a date",""),IF($AE16=1,$AN16,""),$AO16,IF($AD16=0,"",INDEX(Sources[Source issue],$AD16)))) | L16: =IF($AD16=0,"",IF(INDEX(Sources[Agency office],$AD16)="","",INDEX(Sources[Agency office],$AD16))) | M16: =IF($AD16=0,"",IF(INDEX(Sources[Solicitation],$AD16)="","",INDEX(Sources[Solicitation],$AD16))) | N16: =IF($AD16=0,"",IF(INDEX(Sources[Acquisition route],$AD16)="","",INDEX(Sources[Acquisition route],$AD16))) | O16: =IF($AD16=0,"",IF(INDEX(Sources[Location],$AD16)="","",INDEX(Sources[Location],$AD16))) | P16: =IF($AD16=0,"",IF(INDEX(Sources[Release period],$AD16)="","",INDEX(Sources[Release period],$AD16))) | Q16: =IF($AD16=0,"",IF(INDEX(Sources[Award period],$AD16)="","",INDEX(Sources[Award period],$AD16))) | W16: =IF(AND(ISNUMBER($AH16),ISNUMBER($V16),$V16>=0,$V16<=1),ROUND($AH16*$V16,2),"") | Z16: =IF($AD16=0,"",IF(INDEX(Sources[GovTribe URL],$AD16)="","",HYPERLINK(INDEX(Sources[GovTribe URL],$AD16),"Open GovTribe"))) | AD16: =IF($A16="",0,IF(AND($AB16<>"",COUNTIFS(Sources[Source ID],$AB16,Sources[Pursuit ID],$A16)=1,COUNTIFS(Sources[Source ID],$AB16)=1),MATCH($AB16,Sources[Source ID],0),0)) -> 0 | AE16: =IF($AS16=0,"",IF(COUNTIFS(StageMap[Stage],$D16)<>1,"",IF(INDEX(StageMap[Input check],MATCH($D16,StageMap[Stage],0))="",INDEX(StageMap[Active],MATCH($D16,StageMap[Stage],0)),""))) | AF16: =IF($A16="",IF(COUNTA(B16:D16,H16,J16:K16,R16:V16,X16:Y16,AA16:AC16)>0,"Missing pursuit ID",""),IF(COUNTIFS(Pursuits[Pursuit ID],$A16)>1,"Duplicate pursuit ID",IF($B16="","Add opportunity name",""))) | AG16: =IF($A16="","",IF($H16="","",IF(NOT(ISNUMBER($H16)),"Enter a numeric estimate",IF($H16<0,"Estimate cannot be negative",IF($T16<>"Total company contract value","Non-total value excluded",IF($U16="","Add value period","")))))) | AH16: =IF(AND($AE16=1,$AG16="",ISNUMBER($H16)),$H16,"") | AI16: =IF(AND($AE16=1,AND(ISNUMBER(Dashboard!$V$3),Dashboard!$V$3>=1,Dashboard!$V$3<DATE(2099,1,1)),ISNUMBER($E16),$E16>=1,$E16<DATE(2099,1,1),$E16>=Dashboard!$V$3,$E16<Dashboard!$V$3+30),COUNTIFS(Pursuits[Active],1,Pursuits[Response due],">="&Dashboard!$V$3,Pursuits[Response due],"<"&$E16)+COUNTIFS(Pursuits[Active],1,Pursuits[Response due],$E16,Pursuits[Pursuit ID],"<"&$A16)+1,"") | AJ16: =IF(OR($A16="",$AL16=0),"",INDEX(Actions[Action ID],MATCH($A16&"|1",Actions[Pursuit action key],0))) | AK16: =IF($AR16<>1,"",COUNTIFS(Pursuits[Review candidate],1,Pursuits[Pursuit ID],"<"&$A16)+COUNTIFS($A$8:$A16,$A16,$AR$8:$AR16,1)) | AL16: =IF($A16="","",COUNTIFS(Actions[Pursuit ID],$A16,Actions[Open action],1)) | AM16: =IF($A16="","",COUNTIFS(Actions[Pursuit ID],$A16,Actions[Open action],1,Actions[Sort date],DATE(9999,12,31))) | AN16: =IF($AD16=0,"",IF($AC16="","Source not reviewed",IF($AC16<>INDEX(Sources[Source updated],$AD16),"Source changed",""))) | AO16: =IF(OR($AE16<>1,NOT(AND(ISNUMBER(Dashboard!$V$3),Dashboard!$V$3>=1,Dashboard!$V$3<DATE(2099,1,1)))),"",IF($S16="","Not reviewed",IF(NOT(ISNUMBER($S16)),"Use a real review date",IF($S16>Dashboard!$V$3,"Review date is in future",IF(AND(ISNUMBER('Source Data'!$AE$36),'Source Data'!$AE$36>0),IF(Dashboard!$V$3-$S16>'Source Data'!$AE$36,"Review is overdue",""),"Set review interval"))))) | AP16: =IF($AF16<>"",$AF16,IF($A16="","",IF(COUNTIFS(StageMap[Stage],$D16)<>1,"Choose a valid stage",IF(NOT(ISNUMBER($AE16)),"Check stage settings",IF($AB16="","Add source ID",IF($AD16=0,"Source link needs review",IF(INDEX(Sources[Input check],$AD16)<>"",INDEX(Sources[Input check],$AD16),IF(AND($V16<>"",OR(NOT(ISNUMBER($V16)),$V16<0,$V16>1)),"Probability must be 0 to 100%",IF(AND($R16<>"",OR(NOT(ISNUMBER($R16)),$R16<0)),"Use valid duration months",""))))))))) | AQ16: =IF($AD16=0,"",IF(INDEX(Sources[Response time],$AD16)="","Time not confirmed",TEXT(INDEX(Sources[Response time],$AD16),"h:mm AM/PM")&" "&INDEX(Sources[Time zone],$AD16))) | AR16: =IF(AND($I16<>"",OR($AE16=1,$AP16<>"")),1,0) -> 0 | AS16: =IF(AND($A16<>"",$AF16=""),1,0) -> 0
E17: =IF($AD17=0,"",IF(INDEX(Sources[Response date],$AD17)="","",INDEX(Sources[Response date],$AD17))) | F17: =IF($AJ17="","",INDEX(Actions[Action],MATCH($AJ17,Actions[Action ID],0))) | G17: =IF($AJ17="","",IF(INDEX(Actions[Due date],MATCH($AJ17,Actions[Action ID],0))="","",INDEX(Actions[Due date],MATCH($AJ17,Actions[Action ID],0)))) | I17: =IF($A17="",$AF17,_xlfn.TEXTJOIN(CHAR(10),TRUE(),$AP17,$AG17,IF(AND($AE17=1,AND(ISNUMBER(Dashboard!$V$3),Dashboard!$V$3>=1,Dashboard!$V$3<DATE(2099,1,1)),ISNUMBER($E17),$E17<Dashboard!$V$3),"Response date passed",""),IF(AND($AE17=1,$AL17=0),"No next action",""),IF(AND($AE17=1,$AM17>0),"Action needs a date",""),IF($AE17=1,$AN17,""),$AO17,IF($AD17=0,"",INDEX(Sources[Source issue],$AD17)))) | L17: =IF($AD17=0,"",IF(INDEX(Sources[Agency office],$AD17)="","",INDEX(Sources[Agency office],$AD17))) | M17: =IF($AD17=0,"",IF(INDEX(Sources[Solicitation],$AD17)="","",INDEX(Sources[Solicitation],$AD17))) | N17: =IF($AD17=0,"",IF(INDEX(Sources[Acquisition route],$AD17)="","",INDEX(Sources[Acquisition route],$AD17))) | O17: =IF($AD17=0,"",IF(INDEX(Sources[Location],$AD17)="","",INDEX(Sources[Location],$AD17))) | P17: =IF($AD17=0,"",IF(INDEX(Sources[Release period],$AD17)="","",INDEX(Sources[Release period],$AD17))) | Q17: =IF($AD17=0,"",IF(INDEX(Sources[Award period],$AD17)="","",INDEX(Sources[Award period],$AD17))) | W17: =IF(AND(ISNUMBER($AH17),ISNUMBER($V17),$V17>=0,$V17<=1),ROUND($AH17*$V17,2),"") | Z17: =IF($AD17=0,"",IF(INDEX(Sources[GovTribe URL],$AD17)="","",HYPERLINK(INDEX(Sources[GovTribe URL],$AD17),"Open GovTribe"))) | AD17: =IF($A17="",0,IF(AND($AB17<>"",COUNTIFS(Sources[Source ID],$AB17,Sources[Pursuit ID],$A17)=1,COUNTIFS(Sources[Source ID],$AB17)=1),MATCH($AB17,Sources[Source ID],0),0)) -> 0 | AE17: =IF($AS17=0,"",IF(COUNTIFS(StageMap[Stage],$D17)<>1,"",IF(INDEX(StageMap[Input check],MATCH($D17,StageMap[Stage],0))="",INDEX(StageMap[Active],MATCH($D17,StageMap[Stage],0)),""))) | AF17: =IF($A17="",IF(COUNTA(B17:D17,H17,J17:K17,R17:V17,X17:Y17,AA17:AC17)>0,"Missing pursuit ID",""),IF(COUNTIFS(Pursuits[Pursuit ID],$A17)>1,"Duplicate pursuit ID",IF($B17="","Add opportunity name",""))) | AG17: =IF($A17="","",IF($H17="","",IF(NOT(ISNUMBER($H17)),"Enter a numeric estimate",IF($H17<0,"Estimate cannot be negative",IF($T17<>"Total company contract value","Non-total value excluded",IF($U17="","Add value period","")))))) | AH17: =IF(AND($AE17=1,$AG17="",ISNUMBER($H17)),$H17,"") | AI17: =IF(AND($AE17=1,AND(ISNUMBER(Dashboard!$V$3),Dashboard!$V$3>=1,Dashboard!$V$3<DATE(2099,1,1)),ISNUMBER($E17),$E17>=1,$E17<DATE(2099,1,1),$E17>=Dashboard!$V$3,$E17<Dashboard!$V$3+30),COUNTIFS(Pursuits[Active],1,Pursuits[Response due],">="&Dashboard!$V$3,Pursuits[Response due],"<"&$E17)+COUNTIFS(Pursuits[Active],1,Pursuits[Response due],$E17,Pursuits[Pursuit ID],"<"&$A17)+1,"") | AJ17: =IF(OR($A17="",$AL17=0),"",INDEX(Actions[Action ID],MATCH($A17&"|1",Actions[Pursuit action key],0))) | AK17: =IF($AR17<>1,"",COUNTIFS(Pursuits[Review candidate],1,Pursuits[Pursuit ID],"<"&$A17)+COUNTIFS($A$8:$A17,$A17,$AR$8:$AR17,1)) | AL17: =IF($A17="","",COUNTIFS(Actions[Pursuit ID],$A17,Actions[Open action],1)) | AM17: =IF($A17="","",COUNTIFS(Actions[Pursuit ID],$A17,Actions[Open action],1,Actions[Sort date],DATE(9999,12,31))) | AN17: =IF($AD17=0,"",IF($AC17="","Source not reviewed",IF($AC17<>INDEX(Sources[Source updated],$AD17),"Source changed",""))) | AO17: =IF(OR($AE17<>1,NOT(AND(ISNUMBER(Dashboard!$V$3),Dashboard!$V$3>=1,Dashboard!$V$3<DATE(2099,1,1)))),"",IF($S17="","Not reviewed",IF(NOT(ISNUMBER($S17)),"Use a real review date",IF($S17>Dashboard!$V$3,"Review date is in future",IF(AND(ISNUMBER('Source Data'!$AE$36),'Source Data'!$AE$36>0),IF(Dashboard!$V$3-$S17>'Source Data'!$AE$36,"Review is overdue",""),"Set review interval"))))) | AP17: =IF($AF17<>"",$AF17,IF($A17="","",IF(COUNTIFS(StageMap[Stage],$D17)<>1,"Choose a valid stage",IF(NOT(ISNUMBER($AE17)),"Check stage settings",IF($AB17="","Add source ID",IF($AD17=0,"Source link needs review",IF(INDEX(Sources[Input check],$AD17)<>"",INDEX(Sources[Input check],$AD17),IF(AND($V17<>"",OR(NOT(ISNUMBER($V17)),$V17<0,$V17>1)),"Probability must be 0 to 100%",IF(AND($R17<>"",OR(NOT(ISNUMBER($R17)),$R17<0)),"Use valid duration months",""))))))))) | AQ17: =IF($AD17=0,"",IF(INDEX(Sources[Response time],$AD17)="","Time not confirmed",TEXT(INDEX(Sources[Response time],$AD17),"h:mm AM/PM")&" "&INDEX(Sources[Time zone],$AD17))) | AR17: =IF(AND($I17<>"",OR($AE17=1,$AP17<>"")),1,0) -> 0 | AS17: =IF(AND($A17<>"",$AF17=""),1,0) -> 0
