Workbook

Sheet Shortlist
A2: Teaming partner shortlist
A4: Buyer | B4: U.S. Fish and Wildlife Service | E4: As of | F4: 46280
A5: Pursuit | B5: Bitter Lake NWR survey
A6: Prime | B6: GovTribe, Inc. · UEI EDJBUPNLCCL5 | D6: Solicitation | E6: 140FC126R0018
A7: Due | B7: 46289 | C7: 5:00 PM EDT | E7: Submittal | F7: SF330
A8: GovTribe’s identity is real; scenario assumptions and past performance are illustrative. Real opportunity and candidate companies.
A9: =IF(COUNTA(CandidateData[ID])=0,"Add pursuit and candidate inputs to begin.",IF(OR(B4="",B5="",B6="",F4=""),"Complete the pursuit identity above.",COUNTIF(CandidateData[Recommendation],"Shortlist")&" shortlist · "&COUNTIF(CandidateData[Recommendation],"Research further")&" research further · "&COUNTIF(CandidateData[Recommendation],"Exclude")&" exclude"&IF(SUMPRODUCT(--(CandidateData[Input check]<>""))+SUMPRODUCT(--(NeedData[Input check]<>""))+SUMPRODUCT(--(MatchData[Input check]<>""))+SUMPRODUCT(--(WorkData[Input check]<>""))+SUMPRODUCT(--(CheckData[Input check]<>""))+SUMPRODUCT(--(SourceData[Input check]<>""))>0," · Check inputs",""))) -> 2 shortlist · 2 research further · 0 exclude
G10: Next steps and candidate inputs
A11: ID | B11: Company / UEI | C11: Proposed role | D11: Recommendation | E11: Why | F11: Main conditions | G11: Candidate | H11: Next action | I11: Required checks | J11: Source ID | K11: Main issue | L11: Input check
A12: C01 | B12: =IF(A12="","",IF(IF(J12="","Add source ID",IF(NOT(SUMPRODUCT(--(SourceData[ID]=J12))=1),"Unknown or duplicate source",IF(INDEX(SourceData[Input check],MATCH(J12,SourceData[ID],0))<>"","Complete source record","")))<>"","Check vendor source",HYPERLINK(INDEX(SourceData[URL],MATCH(J12,SourceData[ID],0)),INDEX(SourceData[Title],MATCH(J12,SourceData[ID],0))&IF(INDEX(SourceData[UEI],MATCH(J12,SourceData[ID],0))="","",CHAR(10)&"UEI "&INDEX(SourceData[UEI],MATCH(J12,SourceData[ID],0)))))) -> Dewberry Engineers Inc. UEI K3WDSCEDY1V5 | C12: Lead airborne topobathymetric collection. | D12: Shortlist | E12: Green-laser capability disclosure and a NOAA mapping award warrant contact. | F12: =IF(A12="","",K12&CHAR(10)&I12&IF(L12<>"",CHAR(10)&"Check inputs; counts may be incomplete","")) -> Aircraft slot and licensed team are unconfirmed. 0 failed; 7 unresolved | G12: =IF(A12="","",A12&CHAR(10)&B12) -> C01 Dewberry Engineers Inc. UEI K3WDSCEDY1V5 | H12: Ask for a sensor/crew plan, licensed staff and one recent evaluated project. | I12: =IF(A12="","",IF(SUMPRODUCT(--(MatchData[Candidate ID]=A12))+SUMPRODUCT(--((CheckData[Candidate ID]=A12)+(CheckData[Candidate ID]="TEAM")>0))=0,"No assessments recorded",(SUMPRODUCT(--((CheckData[Candidate ID]=A12)+(CheckData[Candidate ID]="TEAM")>0),--(CheckData[Required]="Yes"),--(CheckData[Status]="Fail"))+SUMPRODUCT(--(MatchData[Candidate ID]=A12),--(MatchData[Priority]="Required"),--(MatchData[Status]="Fail")))&" failed; "&(SUMPRODUCT(--((CheckData[Candidate ID]=A12)+(CheckData[Candidate ID]="TEAM")>0),--(CheckData[Required]="Yes"),--(CheckData[Status]="Unresolved"))+SUMPRODUCT(--(MatchData[Candidate ID]=A12),--(MatchData[Priority]="Required"),--(MatchData[Status]="Unresolved")))&" unresolved"&IF(COUNTIF(NeedData[Priority],"Required")>SUMPRODUCT(--(MatchData[Candidate ID]=A12),--(MatchData[Priority]="Required")),"; needs not assessed",""))) -> 0 failed; 7 unresolved | J12: V01 | K12: Aircraft slot and licensed team are unconfirmed. | L12: =IF(NOT(OR(A12<>"",C12<>"",D12<>"",E12<>"",H12<>"",J12<>"",K12<>"")),"",IF(A12="","Add ID",IF(NOT(SUMPRODUCT(--(CandidateData[ID]=A12))=1),"Duplicate ID",IF(IF(J12="","Add source ID",IF(NOT(SUMPRODUCT(--(SourceData[ID]=J12))=1),"Unknown or duplicate source",IF(INDEX(SourceData[Input check],MATCH(J12,SourceData[ID],0))<>"","Complete source record","")))<>"",IF(J12="","Add source ID",IF(NOT(SUMPRODUCT(--(SourceData[ID]=J12))=1),"Unknown or duplicate source",IF(INDEX(SourceData[Input check],MATCH(J12,SourceData[ID],0))<>"","Complete source record",""))),IF(INDEX(SourceData[UEI],MATCH(J12,SourceData[ID],0))="","Add vendor UEI",IF(OR(SUMPRODUCT(--(CandidateData[Source ID]=J12))<>1,SUMPRODUCT(--(CandidateData[ID]<>""),--(RIGHT(CandidateData[Company / UEI],12)=INDEX(SourceData[UEI],MATCH(J12,SourceData[ID],0))))>1),"Duplicate vendor",IF(OR(C12="",E12="",H12="",K12=""),"Add role, reason, issue and action",IF(NOT(OR(D12="Shortlist",D12="Research further",D12="Exclude")),"Choose recommendation",IF(SUMPRODUCT(--(MatchData[Candidate ID]=A12),--(MatchData[Input check]<>""))+SUMPRODUCT(--((CheckData[Candidate ID]=A12)+(CheckData[Candidate ID]="TEAM")>0),--(CheckData[Input check]<>""))>0,"Complete assessments","")))))))))
A13: C02 | B13: =IF(A13="","",IF(IF(J13="","Add source ID",IF(NOT(SUMPRODUCT(--(SourceData[ID]=J13))=1),"Unknown or duplicate source",IF(INDEX(SourceData[Input check],MATCH(J13,SourceData[ID],0))<>"","Complete source record","")))<>"","Check vendor source",HYPERLINK(INDEX(SourceData[URL],MATCH(J13,SourceData[ID],0)),INDEX(SourceData[Title],MATCH(J13,SourceData[ID],0))&IF(INDEX(SourceData[UEI],MATCH(J13,SourceData[ID],0))="","",CHAR(10)&"UEI "&INDEX(SourceData[UEI],MATCH(J13,SourceData[ID],0)))))) -> NV5 Geospatial, Inc. UEI EMJEL3XM6A87 | C13: Alternative lead for airborne collection and processing. | D13: Shortlist | E13: NOAA documents bathymetric work; a recent mapping award warrants contact. | F13: =IF(A13="","",K13&CHAR(10)&I13&IF(L13<>"",CHAR(10)&"Check inputs; counts may be incomplete","")) -> Recent evaluated project and proposed team are unconfirmed. 0 failed; 6 unresolved | G13: =IF(A13="","",A13&CHAR(10)&B13) -> C02 NV5 Geospatial, Inc. UEI EMJEL3XM6A87 | H13: Request a recent project, intended contracting entity and November–February availability. | I13: =IF(A13="","",IF(SUMPRODUCT(--(MatchData[Candidate ID]=A13))+SUMPRODUCT(--((CheckData[Candidate ID]=A13)+(CheckData[Candidate ID]="TEAM")>0))=0,"No assessments recorded",(SUMPRODUCT(--((CheckData[Candidate ID]=A13)+(CheckData[Candidate ID]="TEAM")>0),--(CheckData[Required]="Yes"),--(CheckData[Status]="Fail"))+SUMPRODUCT(--(MatchData[Candidate ID]=A13),--(MatchData[Priority]="Required"),--(MatchData[Status]="Fail")))&" failed; "&(SUMPRODUCT(--((CheckData[Candidate ID]=A13)+(CheckData[Candidate ID]="TEAM")>0),--(CheckData[Required]="Yes"),--(CheckData[Status]="Unresolved"))+SUMPRODUCT(--(MatchData[Candidate ID]=A13),--(MatchData[Priority]="Required"),--(MatchData[Status]="Unresolved")))&" unresolved"&IF(COUNTIF(NeedData[Priority],"Required")>SUMPRODUCT(--(MatchData[Candidate ID]=A13),--(MatchData[Priority]="Required")),"; needs not assessed",""))) -> 0 failed; 6 unresolved | J13: V02 | K13: Recent evaluated project and proposed team are unconfirmed. | L13: =IF(NOT(OR(A13<>"",C13<>"",D13<>"",E13<>"",H13<>"",J13<>"",K13<>"")),"",IF(A13="","Add ID",IF(NOT(SUMPRODUCT(--(CandidateData[ID]=A13))=1),"Duplicate ID",IF(IF(J13="","Add source ID",IF(NOT(SUMPRODUCT(--(SourceData[ID]=J13))=1),"Unknown or duplicate source",IF(INDEX(SourceData[Input check],MATCH(J13,SourceData[ID],0))<>"","Complete source record","")))<>"",IF(J13="","Add source ID",IF(NOT(SUMPRODUCT(--(SourceData[ID]=J13))=1),"Unknown or duplicate source",IF(INDEX(SourceData[Input check],MATCH(J13,SourceData[ID],0))<>"","Complete source record",""))),IF(INDEX(SourceData[UEI],MATCH(J13,SourceData[ID],0))="","Add vendor UEI",IF(OR(SUMPRODUCT(--(CandidateData[Source ID]=J13))<>1,SUMPRODUCT(--(CandidateData[ID]<>""),--(RIGHT(CandidateData[Company / UEI],12)=INDEX(SourceData[UEI],MATCH(J13,SourceData[ID],0))))>1),"Duplicate vendor",IF(OR(C13="",E13="",H13="",K13=""),"Add role, reason, issue and action",IF(NOT(OR(D13="Shortlist",D13="Research further",D13="Exclude")),"Choose recommendation",IF(SUMPRODUCT(--(MatchData[Candidate ID]=A13),--(MatchData[Input check]<>""))+SUMPRODUCT(--((CheckData[Candidate ID]=A13)+(CheckData[Candidate ID]="TEAM")>0),--(CheckData[Input check]<>""))>0,"Complete assessments","")))))))))
A14: C03 | B14: =IF(A14="","",IF(IF(J14="","Add source ID",IF(NOT(SUMPRODUCT(--(SourceData[ID]=J14))=1),"Unknown or duplicate source",IF(INDEX(SourceData[Input check],MATCH(J14,SourceData[ID],0))<>"","Complete source record","")))<>"","Check vendor source",HYPERLINK(INDEX(SourceData[URL],MATCH(J14,SourceData[ID],0)),INDEX(SourceData[Title],MATCH(J14,SourceData[ID],0))&IF(INDEX(SourceData[UEI],MATCH(J14,SourceData[ID],0))="","",CHAR(10)&"UEI "&INDEX(SourceData[UEI],MATCH(J14,SourceData[ID],0)))))) -> Woolpert, Inc. UEI LD8UDJB9JLU1 | C14: Possible LiDAR/imagery collection partner. | D14: Research further | E14: NOAA LiDAR/imagery award is relevant; bathymetric evidence is still missing. | F14: =IF(A14="","",K14&CHAR(10)&I14&IF(L14<>"",CHAR(10)&"Check inputs; counts may be incomplete","")) -> Airborne bathymetric method and staff are unconfirmed. 0 failed; 8 unresolved | G14: =IF(A14="","",A14&CHAR(10)&B14) -> C03 Woolpert, Inc. UEI LD8UDJB9JLU1 | H14: Request a bathymetric method and reference before adding to the contact shortlist. | I14: =IF(A14="","",IF(SUMPRODUCT(--(MatchData[Candidate ID]=A14))+SUMPRODUCT(--((CheckData[Candidate ID]=A14)+(CheckData[Candidate ID]="TEAM")>0))=0,"No assessments recorded",(SUMPRODUCT(--((CheckData[Candidate ID]=A14)+(CheckData[Candidate ID]="TEAM")>0),--(CheckData[Required]="Yes"),--(CheckData[Status]="Fail"))+SUMPRODUCT(--(MatchData[Candidate ID]=A14),--(MatchData[Priority]="Required"),--(MatchData[Status]="Fail")))&" failed; "&(SUMPRODUCT(--((CheckData[Candidate ID]=A14)+(CheckData[Candidate ID]="TEAM")>0),--(CheckData[Required]="Yes"),--(CheckData[Status]="Unresolved"))+SUMPRODUCT(--(MatchData[Candidate ID]=A14),--(MatchData[Priority]="Required"),--(MatchData[Status]="Unresolved")))&" unresolved"&IF(COUNTIF(NeedData[Priority],"Required")>SUMPRODUCT(--(MatchData[Candidate ID]=A14),--(MatchData[Priority]="Required")),"; needs not assessed",""))) -> 0 failed; 8 unresolved | J14: V03 | K14: Airborne bathymetric method and staff are unconfirmed. | L14: =IF(NOT(OR(A14<>"",C14<>"",D14<>"",E14<>"",H14<>"",J14<>"",K14<>"")),"",IF(A14="","Add ID",IF(NOT(SUMPRODUCT(--(CandidateData[ID]=A14))=1),"Duplicate ID",IF(IF(J14="","Add source ID",IF(NOT(SUMPRODUCT(--(SourceData[ID]=J14))=1),"Unknown or duplicate source",IF(INDEX(SourceData[Input check],MATCH(J14,SourceData[ID],0))<>"","Complete source record","")))<>"",IF(J14="","Add source ID",IF(NOT(SUMPRODUCT(--(SourceData[ID]=J14))=1),"Unknown or duplicate source",IF(INDEX(SourceData[Input check],MATCH(J14,SourceData[ID],0))<>"","Complete source record",""))),IF(INDEX(SourceData[UEI],MATCH(J14,SourceData[ID],0))="","Add vendor UEI",IF(OR(SUMPRODUCT(--(CandidateData[Source ID]=J14))<>1,SUMPRODUCT(--(CandidateData[ID]<>""),--(RIGHT(CandidateData[Company / UEI],12)=INDEX(SourceData[UEI],MATCH(J14,SourceData[ID],0))))>1),"Duplicate vendor",IF(OR(C14="",E14="",H14="",K14=""),"Add role, reason, issue and action",IF(NOT(OR(D14="Shortlist",D14="Research further",D14="Exclude")),"Choose recommendation",IF(SUMPRODUCT(--(MatchData[Candidate ID]=A14),--(MatchData[Input check]<>""))+SUMPRODUCT(--((CheckData[Candidate ID]=A14)+(CheckData[Candidate ID]="TEAM")>0),--(CheckData[Input check]<>""))>0,"Complete assessments","")))))))))
A15: C04 | B15: =IF(A15="","",IF(IF(J15="","Add source ID",IF(NOT(SUMPRODUCT(--(SourceData[ID]=J15))=1),"Unknown or duplicate source",IF(INDEX(SourceData[Input check],MATCH(J15,SourceData[ID],0))<>"","Complete source record","")))<>"","Check vendor source",HYPERLINK(INDEX(SourceData[URL],MATCH(J15,SourceData[ID],0)),INDEX(SourceData[Title],MATCH(J15,SourceData[ID],0))&IF(INDEX(SourceData[UEI],MATCH(J15,SourceData[ID],0))="","",CHAR(10)&"UEI "&INDEX(SourceData[UEI],MATCH(J15,SourceData[ID],0)))))) -> Surdex Corporation UEI KHTMVK6LLH11 | C15: Possible topographic LiDAR and imagery support. | D15: Research further | E15: Interior LiDAR/imagery award suggests a supporting role. | F15: =IF(A15="","",K15&CHAR(10)&I15&IF(L15<>"",CHAR(10)&"Check inputs; counts may be incomplete","")) -> Bathymetric capability and workshare are unconfirmed. 0 failed; 8 unresolved | G15: =IF(A15="","",A15&CHAR(10)&B15) -> C04 Surdex Corporation UEI KHTMVK6LLH11 | H15: Confirm interest in a supporting package and whether bathymetric capability is available. | I15: =IF(A15="","",IF(SUMPRODUCT(--(MatchData[Candidate ID]=A15))+SUMPRODUCT(--((CheckData[Candidate ID]=A15)+(CheckData[Candidate ID]="TEAM")>0))=0,"No assessments recorded",(SUMPRODUCT(--((CheckData[Candidate ID]=A15)+(CheckData[Candidate ID]="TEAM")>0),--(CheckData[Required]="Yes"),--(CheckData[Status]="Fail"))+SUMPRODUCT(--(MatchData[Candidate ID]=A15),--(MatchData[Priority]="Required"),--(MatchData[Status]="Fail")))&" failed; "&(SUMPRODUCT(--((CheckData[Candidate ID]=A15)+(CheckData[Candidate ID]="TEAM")>0),--(CheckData[Required]="Yes"),--(CheckData[Status]="Unresolved"))+SUMPRODUCT(--(MatchData[Candidate ID]=A15),--(MatchData[Priority]="Required"),--(MatchData[Status]="Unresolved")))&" unresolved"&IF(COUNTIF(NeedData[Priority],"Required")>SUMPRODUCT(--(MatchData[Candidate ID]=A15),--(MatchData[Priority]="Required")),"; needs not assessed",""))) -> 0 failed; 8 unresolved | J15: V04 | K15: Bathymetric capability and workshare are unconfirmed. | L15: =IF(NOT(OR(A15<>"",C15<>"",D15<>"",E15<>"",H15<>"",J15<>"",K15<>"")),"",IF(A15="","Add ID",IF(NOT(SUMPRODUCT(--(CandidateData[ID]=A15))=1),"Duplicate ID",IF(IF(J15="","Add source ID",IF(NOT(SUMPRODUCT(--(SourceData[ID]=J15))=1),"Unknown or duplicate source",IF(INDEX(SourceData[Input check],MATCH(J15,SourceData[ID],0))<>"","Complete source record","")))<>"",IF(J15="","Add source ID",IF(NOT(SUMPRODUCT(--(SourceData[ID]=J15))=1),"Unknown or duplicate source",IF(INDEX(SourceData[Input check],MATCH(J15,SourceData[ID],0))<>"","Complete source record",""))),IF(INDEX(SourceData[UEI],MATCH(J15,SourceData[ID],0))="","Add vendor UEI",IF(OR(SUMPRODUCT(--(CandidateData[Source ID]=J15))<>1,SUMPRODUCT(--(CandidateData[ID]<>""),--(RIGHT(CandidateData[Company / UEI],12)=INDEX(SourceData[UEI],MATCH(J15,SourceData[ID],0))))>1),"Duplicate vendor",IF(OR(C15="",E15="",H15="",K15=""),"Add role, reason, issue and action",IF(NOT(OR(D15="Shortlist",D15="Research further",D15="Exclude")),"Choose recommendation",IF(SUMPRODUCT(--(MatchData[Candidate ID]=A15),--(MatchData[Input check]<>""))+SUMPRODUCT(--((CheckData[Candidate ID]=A15)+(CheckData[Candidate ID]="TEAM")>0),--(CheckData[Input check]<>""))>0,"Complete assessments","")))))))))
B16: =IF(A16="","",IF(IF(J16="","Add source ID",IF(NOT(SUMPRODUCT(--(SourceData[ID]=J16))=1),"Unknown or duplicate source",IF(INDEX(SourceData[Input check],MATCH(J16,SourceData[ID],0))<>"","Complete source record","")))<>"","Check vendor source",HYPERLINK(INDEX(SourceData[URL],MATCH(J16,SourceData[ID],0)),INDEX(SourceData[Title],MATCH(J16,SourceData[ID],0))&IF(INDEX(SourceData[UEI],MATCH(J16,SourceData[ID],0))="","",CHAR(10)&"UEI "&INDEX(SourceData[UEI],MATCH(J16,SourceData[ID],0)))))) | F16: =IF(A16="","",K16&CHAR(10)&I16&IF(L16<>"",CHAR(10)&"Check inputs; counts may be incomplete","")) | G16: =IF(A16="","",A16&CHAR(10)&B16) | I16: =IF(A16="","",IF(SUMPRODUCT(--(MatchData[Candidate ID]=A16))+SUMPRODUCT(--((CheckData[Candidate ID]=A16)+(CheckData[Candidate ID]="TEAM")>0))=0,"No assessments recorded",(SUMPRODUCT(--((CheckData[Candidate ID]=A16)+(CheckData[Candidate ID]="TEAM")>0),--(CheckData[Required]="Yes"),--(CheckData[Status]="Fail"))+SUMPRODUCT(--(MatchData[Candidate ID]=A16),--(MatchData[Priority]="Required"),--(MatchData[Status]="Fail")))&" failed; "&(SUMPRODUCT(--((CheckData[Candidate ID]=A16)+(CheckData[Candidate ID]="TEAM")>0),--(CheckData[Required]="Yes"),--(CheckData[Status]="Unresolved"))+SUMPRODUCT(--(MatchData[Candidate ID]=A16),--(MatchData[Priority]="Required"),--(MatchData[Status]="Unresolved")))&" unresolved"&IF(COUNTIF(NeedData[Priority],"Required")>SUMPRODUCT(--(MatchData[Candidate ID]=A16),--(MatchData[Priority]="Required")),"; needs not assessed",""))) | L16: =IF(NOT(OR(A16<>"",C16<>"",D16<>"",E16<>"",H16<>"",J16<>"",K16<>"")),"",IF(A16="","Add ID",IF(NOT(SUMPRODUCT(--(CandidateData[ID]=A16))=1),"Duplicate ID",IF(IF(J16="","Add source ID",IF(NOT(SUMPRODUCT(--(SourceData[ID]=J16))=1),"Unknown or duplicate source",IF(INDEX(SourceData[Input check],MATCH(J16,SourceData[ID],0))<>"","Complete source record","")))<>"",IF(J16="","Add source ID",IF(NOT(SUMPRODUCT(--(SourceData[ID]=J16))=1),"Unknown or duplicate source",IF(INDEX(SourceData[Input check],MATCH(J16,SourceData[ID],0))<>"","Complete source record",""))),IF(INDEX(SourceData[UEI],MATCH(J16,SourceData[ID],0))="","Add vendor UEI",IF(OR(SUMPRODUCT(--(CandidateData[Source ID]=J16))<>1,SUMPRODUCT(--(CandidateData[ID]<>""),--(RIGHT(CandidateData[Company / UEI],12)=INDEX(SourceData[UEI],MATCH(J16,SourceData[ID],0))))>1),"Duplicate vendor",IF(OR(C16="",E16="",H16="",K16=""),"Add role, reason, issue and action",IF(NOT(OR(D16="Shortlist",D16="Research further",D16="Exclude")),"Choose recommendation",IF(SUMPRODUCT(--(MatchData[Candidate ID]=A16),--(MatchData[Input check]<>""))+SUMPRODUCT(--((CheckData[Candidate ID]=A16)+(CheckData[Candidate ID]="TEAM")>0),--(CheckData[Input check]<>""))>0,"Complete assessments","")))))))))
B17: =IF(A17="","",IF(IF(J17="","Add source ID",IF(NOT(SUMPRODUCT(--(SourceData[ID]=J17))=1),"Unknown or duplicate source",IF(INDEX(SourceData[Input check],MATCH(J17,SourceData[ID],0))<>"","Complete source record","")))<>"","Check vendor source",HYPERLINK(INDEX(SourceData[URL],MATCH(J17,SourceData[ID],0)),INDEX(SourceData[Title],MATCH(J17,SourceData[ID],0))&IF(INDEX(SourceData[UEI],MATCH(J17,SourceData[ID],0))="","",CHAR(10)&"UEI "&INDEX(SourceData[UEI],MATCH(J17,SourceData[ID],0)))))) | F17: =IF(A17="","",K17&CHAR(10)&I17&IF(L17<>"",CHAR(10)&"Check inputs; counts may be incomplete","")) | G17: =IF(A17="","",A17&CHAR(10)&B17) | I17: =IF(A17="","",IF(SUMPRODUCT(--(MatchData[Candidate ID]=A17))+SUMPRODUCT(--((CheckData[Candidate ID]=A17)+(CheckData[Candidate ID]="TEAM")>0))=0,"No assessments recorded",(SUMPRODUCT(--((CheckData[Candidate ID]=A17)+(CheckData[Candidate ID]="TEAM")>0),--(CheckData[Required]="Yes"),--(CheckData[Status]="Fail"))+SUMPRODUCT(--(MatchData[Candidate ID]=A17),--(MatchData[Priority]="Required"),--(MatchData[Status]="Fail")))&" failed; "&(SUMPRODUCT(--((CheckData[Candidate ID]=A17)+(CheckData[Candidate ID]="TEAM")>0),--(CheckData[Required]="Yes"),--(CheckData[Status]="Unresolved"))+SUMPRODUCT(--(MatchData[Candidate ID]=A17),--(MatchData[Priority]="Required"),--(MatchData[Status]="Unresolved")))&" unresolved"&IF(COUNTIF(NeedData[Priority],"Required")>SUMPRODUCT(--(MatchData[Candidate ID]=A17),--(MatchData[Priority]="Required")),"; needs not assessed",""))) | L17: =IF(NOT(OR(A17<>"",C17<>"",D17<>"",E17<>"",H17<>"",J17<>"",K17<>"")),"",IF(A17="","Add ID",IF(NOT(SUMPRODUCT(--(CandidateData[ID]=A17))=1),"Duplicate ID",IF(IF(J17="","Add source ID",IF(NOT(SUMPRODUCT(--(SourceData[ID]=J17))=1),"Unknown or duplicate source",IF(INDEX(SourceData[Input check],MATCH(J17,SourceData[ID],0))<>"","Complete source record","")))<>"",IF(J17="","Add source ID",IF(NOT(SUMPRODUCT(--(SourceData[ID]=J17))=1),"Unknown or duplicate source",IF(INDEX(SourceData[Input check],MATCH(J17,SourceData[ID],0))<>"","Complete source record",""))),IF(INDEX(SourceData[UEI],MATCH(J17,SourceData[ID],0))="","Add vendor UEI",IF(OR(SUMPRODUCT(--(CandidateData[Source ID]=J17))<>1,SUMPRODUCT(--(CandidateData[ID]<>""),--(RIGHT(CandidateData[Company / UEI],12)=INDEX(SourceData[UEI],MATCH(J17,SourceData[ID],0))))>1),"Duplicate vendor",IF(OR(C17="",E17="",H17="",K17=""),"Add role, reason, issue and action",IF(NOT(OR(D17="Shortlist",D17="Research further",D17="Exclude")),"Choose recommendation",IF(SUMPRODUCT(--(MatchData[Candidate ID]=A17),--(MatchData[Input check]<>""))+SUMPRODUCT(--((CheckData[Candidate ID]=A17)+(CheckData[Candidate ID]="TEAM")>0),--(CheckData[Input check]<>""))>0,"Complete assessments","")))))))))

Sheet Teaming Needs
A2: Teaming needs
A4: Prime capabilities | C4: Illustrative GovTribe capabilities: project coordination and GIS integration only. No aircraft, bathymetric sensor, field crew or named New Mexico licensed manager is assumed.
A6: Teaming structure | C6: Proposed prime/subcontractor team; no partners committed.
A7: Requirements come from the buyer. Gaps describe the prime profile; B01 supports the example assumptions.
A8: ID | B8: Need | C8: Priority | D8: Buyer requirement | E8: Prime gap | F8: Citation | G8: Input check | H8: Source ID | I8: Location
A9: N01 | B9: Airborne bathymetric LiDAR | C9: Required | D9: Airborne bathymetric collection using the October 2025 bathymetric specification. Ground-based bathymetry cannot replace it. | E9: Prime has no bathymetric sensor or flight crew. | F9: =IF(H9="","",IF(IF(H9="","Add source ID",IF(NOT(SUMPRODUCT(--(SourceData[ID]=H9))=1),"Unknown or duplicate source",IF(INDEX(SourceData[Input check],MATCH(H9,SourceData[ID],0))<>"","Complete source record","")))<>"","Check source",IF(INDEX(SourceData[URL],MATCH(H9,SourceData[ID],0))="",H9&IF(I9="",""," "&I9),HYPERLINK(INDEX(SourceData[URL],MATCH(H9,SourceData[ID],0)),H9&IF(I9="",""," "&I9))))) -> S04 pp2,8–9; RFI 01,20,24,25 | G9: =IF(NOT(OR(A9<>"",B9<>"",C9<>"",D9<>"",E9<>"",H9<>"",I9<>"")),"",IF(A9="","Add ID",IF(NOT(SUMPRODUCT(--(NeedData[ID]=A9))=1),"Duplicate ID",IF(OR(B9="",D9="",E9=""),"Add need, requirement and gap",IF(NOT(OR(C9="Required",C9="Preferred")),"Choose priority",IF(H9="","Add source ID",IF(NOT(SUMPRODUCT(--(SourceData[ID]=H9))=1),"Unknown or duplicate source",IF(INDEX(SourceData[Input check],MATCH(H9,SourceData[ID],0))<>"","Complete source record","")))))))) | H9: S04 | I9: pp2,8–9; RFI 01,20,24,25
A10: N02 | B10: Topographic LiDAR and imagery | C10: Required | D10: Topographic collection at 8 points/m² or better, plus 3-inch, four-band orthophotography. | E10: Prime has no aircraft or image acquisition equipment. | F10: =IF(H10="","",IF(IF(H10="","Add source ID",IF(NOT(SUMPRODUCT(--(SourceData[ID]=H10))=1),"Unknown or duplicate source",IF(INDEX(SourceData[Input check],MATCH(H10,SourceData[ID],0))<>"","Complete source record","")))<>"","Check source",IF(INDEX(SourceData[URL],MATCH(H10,SourceData[ID],0))="",H10&IF(I10="",""," "&I10),HYPERLINK(INDEX(SourceData[URL],MATCH(H10,SourceData[ID],0)),H10&IF(I10="",""," "&I10))))) -> S02 pp5–6,10–11 | G10: =IF(NOT(OR(A10<>"",B10<>"",C10<>"",D10<>"",E10<>"",H10<>"",I10<>"")),"",IF(A10="","Add ID",IF(NOT(SUMPRODUCT(--(NeedData[ID]=A10))=1),"Duplicate ID",IF(OR(B10="",D10="",E10=""),"Add need, requirement and gap",IF(NOT(OR(C10="Required",C10="Preferred")),"Choose priority",IF(H10="","Add source ID",IF(NOT(SUMPRODUCT(--(SourceData[ID]=H10))=1),"Unknown or duplicate source",IF(INDEX(SourceData[Input check],MATCH(H10,SourceData[ID],0))<>"","Complete source record","")))))))) | H10: S02 | I10: pp5–6,10–11
A11: N03 | B11: Ground control and field survey | C11: Required | D11: Six primary control points in the Middle/South tracts and detailed surveys of 20 water-control structures. Visible utilities are sufficient. | E11: Prime has no field crew or named New Mexico survey professional. | F11: =IF(H11="","",IF(IF(H11="","Add source ID",IF(NOT(SUMPRODUCT(--(SourceData[ID]=H11))=1),"Unknown or duplicate source",IF(INDEX(SourceData[Input check],MATCH(H11,SourceData[ID],0))<>"","Complete source record","")))<>"","Check source",IF(INDEX(SourceData[URL],MATCH(H11,SourceData[ID],0))="",H11&IF(I11="",""," "&I11),HYPERLINK(INDEX(SourceData[URL],MATCH(H11,SourceData[ID],0)),H11&IF(I11="",""," "&I11))))) -> S04 pp2–3,9; RFI 04,06,25 | G11: =IF(NOT(OR(A11<>"",B11<>"",C11<>"",D11<>"",E11<>"",H11<>"",I11<>"")),"",IF(A11="","Add ID",IF(NOT(SUMPRODUCT(--(NeedData[ID]=A11))=1),"Duplicate ID",IF(OR(B11="",D11="",E11=""),"Add need, requirement and gap",IF(NOT(OR(C11="Required",C11="Preferred")),"Choose priority",IF(H11="","Add source ID",IF(NOT(SUMPRODUCT(--(SourceData[ID]=H11))=1),"Unknown or duplicate source",IF(INDEX(SourceData[Input check],MATCH(H11,SourceData[ID],0))<>"","Complete source record","")))))))) | H11: S04 | I11: pp2–3,9; RFI 04,06,25
A12: N04 | B12: LiDAR processing and delivery | C12: Required | D12: Deliver hydro-flattened and topobathymetric DEMs and an ESRI breakline geodatabase, with the specified quality checks. | E12: Prime can integrate GIS outputs; specialist bathymetric processing and validation are not assumed. | F12: =IF(H12="","",IF(IF(H12="","Add source ID",IF(NOT(SUMPRODUCT(--(SourceData[ID]=H12))=1),"Unknown or duplicate source",IF(INDEX(SourceData[Input check],MATCH(H12,SourceData[ID],0))<>"","Complete source record","")))<>"","Check source",IF(INDEX(SourceData[URL],MATCH(H12,SourceData[ID],0))="",H12&IF(I12="",""," "&I12),HYPERLINK(INDEX(SourceData[URL],MATCH(H12,SourceData[ID],0)),H12&IF(I12="",""," "&I12))))) -> S04 pp4–5,9; RFI 09,23 | G12: =IF(NOT(OR(A12<>"",B12<>"",C12<>"",D12<>"",E12<>"",H12<>"",I12<>"")),"",IF(A12="","Add ID",IF(NOT(SUMPRODUCT(--(NeedData[ID]=A12))=1),"Duplicate ID",IF(OR(B12="",D12="",E12=""),"Add need, requirement and gap",IF(NOT(OR(C12="Required",C12="Preferred")),"Choose priority",IF(H12="","Add source ID",IF(NOT(SUMPRODUCT(--(SourceData[ID]=H12))=1),"Unknown or duplicate source",IF(INDEX(SourceData[Input check],MATCH(H12,SourceData[ID],0))<>"","Complete source record","")))))))) | H12: S04 | I12: pp4–5,9; RFI 09,23
F13: =IF(H13="","",IF(IF(H13="","Add source ID",IF(NOT(SUMPRODUCT(--(SourceData[ID]=H13))=1),"Unknown or duplicate source",IF(INDEX(SourceData[Input check],MATCH(H13,SourceData[ID],0))<>"","Complete source record","")))<>"","Check source",IF(INDEX(SourceData[URL],MATCH(H13,SourceData[ID],0))="",H13&IF(I13="",""," "&I13),HYPERLINK(INDEX(SourceData[URL],MATCH(H13,SourceData[ID],0)),H13&IF(I13="",""," "&I13))))) | G13: =IF(NOT(OR(A13<>"",B13<>"",C13<>"",D13<>"",E13<>"",H13<>"",I13<>"")),"",IF(A13="","Add ID",IF(NOT(SUMPRODUCT(--(NeedData[ID]=A13))=1),"Duplicate ID",IF(OR(B13="",D13="",E13=""),"Add need, requirement and gap",IF(NOT(OR(C13="Required",C13="Preferred")),"Choose priority",IF(H13="","Add source ID",IF(NOT(SUMPRODUCT(--(SourceData[ID]=H13))=1),"Unknown or duplicate source",IF(INDEX(SourceData[Input check],MATCH(H13,SourceData[ID],0))<>"","Complete source record",""))))))))
F14: =IF(H14="","",IF(IF(H14="","Add source ID",IF(NOT(SUMPRODUCT(--(SourceData[ID]=H14))=1),"Unknown or duplicate source",IF(INDEX(SourceData[Input check],MATCH(H14,SourceData[ID],0))<>"","Complete source record","")))<>"","Check source",IF(INDEX(SourceData[URL],MATCH(H14,SourceData[ID],0))="",H14&IF(I14="",""," "&I14),HYPERLINK(INDEX(SourceData[URL],MATCH(H14,SourceData[ID],0)),H14&IF(I14="",""," "&I14))))) | G14: =IF(NOT(OR(A14<>"",B14<>"",C14<>"",D14<>"",E14<>"",H14<>"",I14<>"")),"",IF(A14="","Add ID",IF(NOT(SUMPRODUCT(--(NeedData[ID]=A14))=1),"Duplicate ID",IF(OR(B14="",D14="",E14=""),"Add need, requirement and gap",IF(NOT(OR(C14="Required",C14="Preferred")),"Choose priority",IF(H14="","Add source ID",IF(NOT(SUMPRODUCT(--(SourceData[ID]=H14))=1),"Unknown or duplicate source",IF(INDEX(SourceData[Input check],MATCH(H14,SourceData[ID],0))<>"","Complete source record",""))))))))

Sheet Capability Match
A2: Capability match
A4: Assess the stated public evidence, not readiness to perform. A supported capability still needs the pursuit-specific confirmations in the last column.
A7: ID | B7: Candidate ID | C7: Need ID | D7: Status | E7: Evidence assessment | F7: Citation | G7: What we need to get | H7: Input check | I7: Source ID | J7: Location | K7: Priority
A8: M11 | B8: C01 | C8: N01 | D8: Pass | E8: Dewberry reports a green-laser sensor for topographic and bathymetric mapping. Allocation to this legal entity and pursuit is unconfirmed. | F8: =IF(I8="","",IF(IF(I8="","Add source ID",IF(NOT(SUMPRODUCT(--(SourceData[ID]=I8))=1),"Unknown or duplicate source",IF(INDEX(SourceData[Input check],MATCH(I8,SourceData[ID],0))<>"","Complete source record","")))<>"","Check source",IF(INDEX(SourceData[URL],MATCH(I8,SourceData[ID],0))="",I8&IF(J8="",""," "&J8),HYPERLINK(INDEX(SourceData[URL],MATCH(I8,SourceData[ID],0)),I8&IF(J8="",""," "&J8))))) -> T01 Company announcement | G8: Provide the proposed airborne method, sensor and a relevant project. | H8: =IF(NOT(OR(A8<>"",B8<>"",C8<>"",D8<>"",E8<>"",G8<>"",I8<>"",J8<>"")),"",IF(A8="","Add ID",IF(NOT(SUMPRODUCT(--(MatchData[ID]=A8))=1),"Duplicate ID",IF(IF(B8="","Add candidate ID",IF(NOT(SUMPRODUCT(--(CandidateData[ID]=B8))=1),"Unknown or duplicate candidate",""))<>"",IF(B8="","Add candidate ID",IF(NOT(SUMPRODUCT(--(CandidateData[ID]=B8))=1),"Unknown or duplicate candidate","")),IF(IF(C8="","Add need ID",IF(NOT(SUMPRODUCT(--(NeedData[ID]=C8))=1),"Unknown or duplicate need",IF(INDEX(NeedData[Input check],MATCH(C8,NeedData[ID],0))<>"","Complete teaming need","")))<>"",IF(C8="","Add need ID",IF(NOT(SUMPRODUCT(--(NeedData[ID]=C8))=1),"Unknown or duplicate need",IF(INDEX(NeedData[Input check],MATCH(C8,NeedData[ID],0))<>"","Complete teaming need",""))),IF(SUMPRODUCT(--(MatchData[Candidate ID]=B8),--(MatchData[Need ID]=C8))<>1,"Duplicate candidate/need",IF(NOT(OR(D8="Pass",D8="Fail",D8="Unresolved")),"Choose status",IF(OR(E8="",G8=""),"Add assessment and next step",IF(AND(D8<>"Unresolved",I8=""),"Add evidence source",IF(I8="","",IF(I8="","Add source ID",IF(NOT(SUMPRODUCT(--(SourceData[ID]=I8))=1),"Unknown or duplicate source",IF(INDEX(SourceData[Input check],MATCH(I8,SourceData[ID],0))<>"","Complete source record",""))))))))))))) | I8: T01 | J8: Company announcement | K8: =IF(C8="","",IF(IF(C8="","Add need ID",IF(NOT(SUMPRODUCT(--(NeedData[ID]=C8))=1),"Unknown or duplicate need",IF(INDEX(NeedData[Input check],MATCH(C8,NeedData[ID],0))<>"","Complete teaming need","")))<>"","",INDEX(NeedData[Priority],MATCH(C8,NeedData[ID],0)))) -> Required
A9: M12 | B9: C01 | C9: N02 | D9: Pass | E9: Public award scope includes LiDAR and imagery. This supports relevant work scope, not compliance with every Bitter Lake specification. | F9: =IF(I9="","",IF(IF(I9="","Add source ID",IF(NOT(SUMPRODUCT(--(SourceData[ID]=I9))=1),"Unknown or duplicate source",IF(INDEX(SourceData[Input check],MATCH(I9,SourceData[ID],0))<>"","Complete source record","")))<>"","Check source",IF(INDEX(SourceData[URL],MATCH(I9,SourceData[ID],0))="",I9&IF(J9="",""," "&J9),HYPERLINK(INDEX(SourceData[URL],MATCH(I9,SourceData[ID],0)),I9&IF(J9="",""," "&J9))))) -> W01 Raw award description | G9: Confirm the specified point density, four-band imagery and proposed equipment. | H9: =IF(NOT(OR(A9<>"",B9<>"",C9<>"",D9<>"",E9<>"",G9<>"",I9<>"",J9<>"")),"",IF(A9="","Add ID",IF(NOT(SUMPRODUCT(--(MatchData[ID]=A9))=1),"Duplicate ID",IF(IF(B9="","Add candidate ID",IF(NOT(SUMPRODUCT(--(CandidateData[ID]=B9))=1),"Unknown or duplicate candidate",""))<>"",IF(B9="","Add candidate ID",IF(NOT(SUMPRODUCT(--(CandidateData[ID]=B9))=1),"Unknown or duplicate candidate","")),IF(IF(C9="","Add need ID",IF(NOT(SUMPRODUCT(--(NeedData[ID]=C9))=1),"Unknown or duplicate need",IF(INDEX(NeedData[Input check],MATCH(C9,NeedData[ID],0))<>"","Complete teaming need","")))<>"",IF(C9="","Add need ID",IF(NOT(SUMPRODUCT(--(NeedData[ID]=C9))=1),"Unknown or duplicate need",IF(INDEX(NeedData[Input check],MATCH(C9,NeedData[ID],0))<>"","Complete teaming need",""))),IF(SUMPRODUCT(--(MatchData[Candidate ID]=B9),--(MatchData[Need ID]=C9))<>1,"Duplicate candidate/need",IF(NOT(OR(D9="Pass",D9="Fail",D9="Unresolved")),"Choose status",IF(OR(E9="",G9=""),"Add assessment and next step",IF(AND(D9<>"Unresolved",I9=""),"Add evidence source",IF(I9="","",IF(I9="","Add source ID",IF(NOT(SUMPRODUCT(--(SourceData[ID]=I9))=1),"Unknown or duplicate source",IF(INDEX(SourceData[Input check],MATCH(I9,SourceData[ID],0))<>"","Complete source record",""))))))))))))) | I9: W01 | J9: Raw award description | K9: =IF(C9="","",IF(IF(C9="","Add need ID",IF(NOT(SUMPRODUCT(--(NeedData[ID]=C9))=1),"Unknown or duplicate need",IF(INDEX(NeedData[Input check],MATCH(C9,NeedData[ID],0))<>"","Complete teaming need","")))<>"","",INDEX(NeedData[Priority],MATCH(C9,NeedData[ID],0)))) -> Required
A10: M13 | B10: C01 | C10: N03 | D10: Unresolved | E10: The inspected public records do not establish this capability for the proposed team. | F10: =IF(I10="","",IF(IF(I10="","Add source ID",IF(NOT(SUMPRODUCT(--(SourceData[ID]=I10))=1),"Unknown or duplicate source",IF(INDEX(SourceData[Input check],MATCH(I10,SourceData[ID],0))<>"","Complete source record","")))<>"","Check source",IF(INDEX(SourceData[URL],MATCH(I10,SourceData[ID],0))="",I10&IF(J10="",""," "&J10),HYPERLINK(INDEX(SourceData[URL],MATCH(I10,SourceData[ID],0)),I10&IF(J10="",""," "&J10))))) | G10: Identify the field crew, New Mexico license holders and survey deliverables. | H10: =IF(NOT(OR(A10<>"",B10<>"",C10<>"",D10<>"",E10<>"",G10<>"",I10<>"",J10<>"")),"",IF(A10="","Add ID",IF(NOT(SUMPRODUCT(--(MatchData[ID]=A10))=1),"Duplicate ID",IF(IF(B10="","Add candidate ID",IF(NOT(SUMPRODUCT(--(CandidateData[ID]=B10))=1),"Unknown or duplicate candidate",""))<>"",IF(B10="","Add candidate ID",IF(NOT(SUMPRODUCT(--(CandidateData[ID]=B10))=1),"Unknown or duplicate candidate","")),IF(IF(C10="","Add need ID",IF(NOT(SUMPRODUCT(--(NeedData[ID]=C10))=1),"Unknown or duplicate need",IF(INDEX(NeedData[Input check],MATCH(C10,NeedData[ID],0))<>"","Complete teaming need","")))<>"",IF(C10="","Add need ID",IF(NOT(SUMPRODUCT(--(NeedData[ID]=C10))=1),"Unknown or duplicate need",IF(INDEX(NeedData[Input check],MATCH(C10,NeedData[ID],0))<>"","Complete teaming need",""))),IF(SUMPRODUCT(--(MatchData[Candidate ID]=B10),--(MatchData[Need ID]=C10))<>1,"Duplicate candidate/need",IF(NOT(OR(D10="Pass",D10="Fail",D10="Unresolved")),"Choose status",IF(OR(E10="",G10=""),"Add assessment and next step",IF(AND(D10<>"Unresolved",I10=""),"Add evidence source",IF(I10="","",IF(I10="","Add source ID",IF(NOT(SUMPRODUCT(--(SourceData[ID]=I10))=1),"Unknown or duplicate source",IF(INDEX(SourceData[Input check],MATCH(I10,SourceData[ID],0))<>"","Complete source record",""))))))))))))) | K10: =IF(C10="","",IF(IF(C10="","Add need ID",IF(NOT(SUMPRODUCT(--(NeedData[ID]=C10))=1),"Unknown or duplicate need",IF(INDEX(NeedData[Input check],MATCH(C10,NeedData[ID],0))<>"","Complete teaming need","")))<>"","",INDEX(NeedData[Priority],MATCH(C10,NeedData[ID],0)))) -> Required
A11: M14 | B11: C01 | C11: N04 | D11: Unresolved | E11: The inspected public records do not establish this capability for the proposed team. | F11: =IF(I11="","",IF(IF(I11="","Add source ID",IF(NOT(SUMPRODUCT(--(SourceData[ID]=I11))=1),"Unknown or duplicate source",IF(INDEX(SourceData[Input check],MATCH(I11,SourceData[ID],0))<>"","Complete source record","")))<>"","Check source",IF(INDEX(SourceData[URL],MATCH(I11,SourceData[ID],0))="",I11&IF(J11="",""," "&J11),HYPERLINK(INDEX(SourceData[URL],MATCH(I11,SourceData[ID],0)),I11&IF(J11="",""," "&J11))))) | G11: Provide a deliverable sample, QA approach and the responsible processing team. | H11: =IF(NOT(OR(A11<>"",B11<>"",C11<>"",D11<>"",E11<>"",G11<>"",I11<>"",J11<>"")),"",IF(A11="","Add ID",IF(NOT(SUMPRODUCT(--(MatchData[ID]=A11))=1),"Duplicate ID",IF(IF(B11="","Add candidate ID",IF(NOT(SUMPRODUCT(--(CandidateData[ID]=B11))=1),"Unknown or duplicate candidate",""))<>"",IF(B11="","Add candidate ID",IF(NOT(SUMPRODUCT(--(CandidateData[ID]=B11))=1),"Unknown or duplicate candidate","")),IF(IF(C11="","Add need ID",IF(NOT(SUMPRODUCT(--(NeedData[ID]=C11))=1),"Unknown or duplicate need",IF(INDEX(NeedData[Input check],MATCH(C11,NeedData[ID],0))<>"","Complete teaming need","")))<>"",IF(C11="","Add need ID",IF(NOT(SUMPRODUCT(--(NeedData[ID]=C11))=1),"Unknown or duplicate need",IF(INDEX(NeedData[Input check],MATCH(C11,NeedData[ID],0))<>"","Complete teaming need",""))),IF(SUMPRODUCT(--(MatchData[Candidate ID]=B11),--(MatchData[Need ID]=C11))<>1,"Duplicate candidate/need",IF(NOT(OR(D11="Pass",D11="Fail",D11="Unresolved")),"Choose status",IF(OR(E11="",G11=""),"Add assessment and next step",IF(AND(D11<>"Unresolved",I11=""),"Add evidence source",IF(I11="","",IF(I11="","Add source ID",IF(NOT(SUMPRODUCT(--(SourceData[ID]=I11))=1),"Unknown or duplicate source",IF(INDEX(SourceData[Input check],MATCH(I11,SourceData[ID],0))<>"","Complete source record",""))))))))))))) | K11: =IF(C11="","",IF(IF(C11="","Add need ID",IF(NOT(SUMPRODUCT(--(NeedData[ID]=C11))=1),"Unknown or duplicate need",IF(INDEX(NeedData[Input check],MATCH(C11,NeedData[ID],0))<>"","Complete teaming need","")))<>"","",INDEX(NeedData[Priority],MATCH(C11,NeedData[ID],0)))) -> Required
A12: M21 | B12: C02 | C12: N01 | D12: Pass | E12: NOAA records NV5 collection and processing of coastal topobathymetric data in 2019–2020. Current staff and entity continuity need confirmation. | F12: =IF(I12="","",IF(IF(I12="","Add source ID",IF(NOT(SUMPRODUCT(--(SourceData[ID]=I12))=1),"Unknown or duplicate source",IF(INDEX(SourceData[Input check],MATCH(I12,SourceData[ID],0))<>"","Complete source record","")))<>"","Check source",IF(INDEX(SourceData[URL],MATCH(I12,SourceData[ID],0))="",I12&IF(J12="",""," "&J12),HYPERLINK(INDEX(SourceData[URL],MATCH(I12,SourceData[ID],0)),I12&IF(J12="",""," "&J12))))) -> T02 Abstract; supplemental information | G12: Provide the proposed airborne method, sensor and a relevant project. | H12: =IF(NOT(OR(A12<>"",B12<>"",C12<>"",D12<>"",E12<>"",G12<>"",I12<>"",J12<>"")),"",IF(A12="","Add ID",IF(NOT(SUMPRODUCT(--(MatchData[ID]=A12))=1),"Duplicate ID",IF(IF(B12="","Add candidate ID",IF(NOT(SUMPRODUCT(--(CandidateData[ID]=B12))=1),"Unknown or duplicate candidate",""))<>"",IF(B12="","Add candidate ID",IF(NOT(SUMPRODUCT(--(CandidateData[ID]=B12))=1),"Unknown or duplicate candidate","")),IF(IF(C12="","Add need ID",IF(NOT(SUMPRODUCT(--(NeedData[ID]=C12))=1),"Unknown or duplicate need",IF(INDEX(NeedData[Input check],MATCH(C12,NeedData[ID],0))<>"","Complete teaming need","")))<>"",IF(C12="","Add need ID",IF(NOT(SUMPRODUCT(--(NeedData[ID]=C12))=1),"Unknown or duplicate need",IF(INDEX(NeedData[Input check],MATCH(C12,NeedData[ID],0))<>"","Complete teaming need",""))),IF(SUMPRODUCT(--(MatchData[Candidate ID]=B12),--(MatchData[Need ID]=C12))<>1,"Duplicate candidate/need",IF(NOT(OR(D12="Pass",D12="Fail",D12="Unresolved")),"Choose status",IF(OR(E12="",G12=""),"Add assessment and next step",IF(AND(D12<>"Unresolved",I12=""),"Add evidence source",IF(I12="","",IF(I12="","Add source ID",IF(NOT(SUMPRODUCT(--(SourceData[ID]=I12))=1),"Unknown or duplicate source",IF(INDEX(SourceData[Input check],MATCH(I12,SourceData[ID],0))<>"","Complete source record",""))))))))))))) | I12: T02 | J12: Abstract; supplemental information | K12: =IF(C12="","",IF(IF(C12="","Add need ID",IF(NOT(SUMPRODUCT(--(NeedData[ID]=C12))=1),"Unknown or duplicate need",IF(INDEX(NeedData[Input check],MATCH(C12,NeedData[ID],0))<>"","Complete teaming need","")))<>"","",INDEX(NeedData[Priority],MATCH(C12,NeedData[ID],0)))) -> Required
A13: M22 | B13: C02 | C13: N02 | D13: Pass | E13: Public award scope includes LiDAR and imagery. This supports relevant work scope, not compliance with every Bitter Lake specification. | F13: =IF(I13="","",IF(IF(I13="","Add source ID",IF(NOT(SUMPRODUCT(--(SourceData[ID]=I13))=1),"Unknown or duplicate source",IF(INDEX(SourceData[Input check],MATCH(I13,SourceData[ID],0))<>"","Complete source record","")))<>"","Check source",IF(INDEX(SourceData[URL],MATCH(I13,SourceData[ID],0))="",I13&IF(J13="",""," "&J13),HYPERLINK(INDEX(SourceData[URL],MATCH(I13,SourceData[ID],0)),I13&IF(J13="",""," "&J13))))) -> W02 Raw award description | G13: Confirm the specified point density, four-band imagery and proposed equipment. | H13: =IF(NOT(OR(A13<>"",B13<>"",C13<>"",D13<>"",E13<>"",G13<>"",I13<>"",J13<>"")),"",IF(A13="","Add ID",IF(NOT(SUMPRODUCT(--(MatchData[ID]=A13))=1),"Duplicate ID",IF(IF(B13="","Add candidate ID",IF(NOT(SUMPRODUCT(--(CandidateData[ID]=B13))=1),"Unknown or duplicate candidate",""))<>"",IF(B13="","Add candidate ID",IF(NOT(SUMPRODUCT(--(CandidateData[ID]=B13))=1),"Unknown or duplicate candidate","")),IF(IF(C13="","Add need ID",IF(NOT(SUMPRODUCT(--(NeedData[ID]=C13))=1),"Unknown or duplicate need",IF(INDEX(NeedData[Input check],MATCH(C13,NeedData[ID],0))<>"","Complete teaming need","")))<>"",IF(C13="","Add need ID",IF(NOT(SUMPRODUCT(--(NeedData[ID]=C13))=1),"Unknown or duplicate need",IF(INDEX(NeedData[Input check],MATCH(C13,NeedData[ID],0))<>"","Complete teaming need",""))),IF(SUMPRODUCT(--(MatchData[Candidate ID]=B13),--(MatchData[Need ID]=C13))<>1,"Duplicate candidate/need",IF(NOT(OR(D13="Pass",D13="Fail",D13="Unresolved")),"Choose status",IF(OR(E13="",G13=""),"Add assessment and next step",IF(AND(D13<>"Unresolved",I13=""),"Add evidence source",IF(I13="","",IF(I13="","Add source ID",IF(NOT(SUMPRODUCT(--(SourceData[ID]=I13))=1),"Unknown or duplicate source",IF(INDEX(SourceData[Input check],MATCH(I13,SourceData[ID],0))<>"","Complete source record",""))))))))))))) | I13: W02 | J13: Raw award description | K13: =IF(C13="","",IF(IF(C13="","Add need ID",IF(NOT(SUMPRODUCT(--(NeedData[ID]=C13))=1),"Unknown or duplicate need",IF(INDEX(NeedData[Input check],MATCH(C13,NeedData[ID],0))<>"","Complete teaming need","")))<>"","",INDEX(NeedData[Priority],MATCH(C13,NeedData[ID],0)))) -> Required
A14: M23 | B14: C02 | C14: N03 | D14: Unresolved | E14: The inspected public records do not establish this capability for the proposed team. | F14: =IF(I14="","",IF(IF(I14="","Add source ID",IF(NOT(SUMPRODUCT(--(SourceData[ID]=I14))=1),"Unknown or duplicate source",IF(INDEX(SourceData[Input check],MATCH(I14,SourceData[ID],0))<>"","Complete source record","")))<>"","Check source",IF(INDEX(SourceData[URL],MATCH(I14,SourceData[ID],0))="",I14&IF(J14="",""," "&J14),HYPERLINK(INDEX(SourceData[URL],MATCH(I14,SourceData[ID],0)),I14&IF(J14="",""," "&J14))))) | G14: Identify the field crew, New Mexico license holders and survey deliverables. | H14: =IF(NOT(OR(A14<>"",B14<>"",C14<>"",D14<>"",E14<>"",G14<>"",I14<>"",J14<>"")),"",IF(A14="","Add ID",IF(NOT(SUMPRODUCT(--(MatchData[ID]=A14))=1),"Duplicate ID",IF(IF(B14="","Add candidate ID",IF(NOT(SUMPRODUCT(--(CandidateData[ID]=B14))=1),"Unknown or duplicate candidate",""))<>"",IF(B14="","Add candidate ID",IF(NOT(SUMPRODUCT(--(CandidateData[ID]=B14))=1),"Unknown or duplicate candidate","")),IF(IF(C14="","Add need ID",IF(NOT(SUMPRODUCT(--(NeedData[ID]=C14))=1),"Unknown or duplicate need",IF(INDEX(NeedData[Input check],MATCH(C14,NeedData[ID],0))<>"","Complete teaming need","")))<>"",IF(C14="","Add need ID",IF(NOT(SUMPRODUCT(--(NeedData[ID]=C14))=1),"Unknown or duplicate need",IF(INDEX(NeedData[Input check],MATCH(C14,NeedData[ID],0))<>"","Complete teaming need",""))),IF(SUMPRODUCT(--(MatchData[Candidate ID]=B14),--(MatchData[Need ID]=C14))<>1,"Duplicate candidate/need",IF(NOT(OR(D14="Pass",D14="Fail",D14="Unresolved")),"Choose status",IF(OR(E14="",G14=""),"Add assessment and next step",IF(AND(D14<>"Unresolved",I14=""),"Add evidence source",IF(I14="","",IF(I14="","Add source ID",IF(NOT(SUMPRODUCT(--(SourceData[ID]=I14))=1),"Unknown or duplicate source",IF(INDEX(SourceData[Input check],MATCH(I14,SourceData[ID],0))<>"","Complete source record",""))))))))))))) | K14: =IF(C14="","",IF(IF(C14="","Add need ID",IF(NOT(SUMPRODUCT(--(NeedData[ID]=C14))=1),"Unknown or duplicate need",IF(INDEX(NeedData[Input check],MATCH(C14,NeedData[ID],0))<>"","Complete teaming need","")))<>"","",INDEX(NeedData[Priority],MATCH(C14,NeedData[ID],0)))) -> Required
A15: M24 | B15: C02 | C15: N04 | D15: Pass | E15: NOAA records NV5 collection and processing of coastal topobathymetric data in 2019–2020. Current staff and entity continuity need confirmation. | F15: =IF(I15="","",IF(IF(I15="","Add source ID",IF(NOT(SUMPRODUCT(--(SourceData[ID]=I15))=1),"Unknown or duplicate source",IF(INDEX(SourceData[Input check],MATCH(I15,SourceData[ID],0))<>"","Complete source record","")))<>"","Check source",IF(INDEX(SourceData[URL],MATCH(I15,SourceData[ID],0))="",I15&IF(J15="",""," "&J15),HYPERLINK(INDEX(SourceData[URL],MATCH(I15,SourceData[ID],0)),I15&IF(J15="",""," "&J15))))) -> T02 Abstract; supplemental information | G15: Provide a deliverable sample, QA approach and the responsible processing team. | H15: =IF(NOT(OR(A15<>"",B15<>"",C15<>"",D15<>"",E15<>"",G15<>"",I15<>"",J15<>"")),"",IF(A15="","Add ID",IF(NOT(SUMPRODUCT(--(MatchData[ID]=A15))=1),"Duplicate ID",IF(IF(B15="","Add candidate ID",IF(NOT(SUMPRODUCT(--(CandidateData[ID]=B15))=1),"Unknown or duplicate candidate",""))<>"",IF(B15="","Add candidate ID",IF(NOT(SUMPRODUCT(--(CandidateData[ID]=B15))=1),"Unknown or duplicate candidate","")),IF(IF(C15="","Add need ID",IF(NOT(SUMPRODUCT(--(NeedData[ID]=C15))=1),"Unknown or duplicate need",IF(INDEX(NeedData[Input check],MATCH(C15,NeedData[ID],0))<>"","Complete teaming need","")))<>"",IF(C15="","Add need ID",IF(NOT(SUMPRODUCT(--(NeedData[ID]=C15))=1),"Unknown or duplicate need",IF(INDEX(NeedData[Input check],MATCH(C15,NeedData[ID],0))<>"","Complete teaming need",""))),IF(SUMPRODUCT(--(MatchData[Candidate ID]=B15),--(MatchData[Need ID]=C15))<>1,"Duplicate candidate/need",IF(NOT(OR(D15="Pass",D15="Fail",D15="Unresolved")),"Choose status",IF(OR(E15="",G15=""),"Add assessment and next step",IF(AND(D15<>"Unresolved",I15=""),"Add evidence source",IF(I15="","",IF(I15="","Add source ID",IF(NOT(SUMPRODUCT(--(SourceData[ID]=I15))=1),"Unknown or duplicate source",IF(INDEX(SourceData[Input check],MATCH(I15,SourceData[ID],0))<>"","Complete source record",""))))))))))))) | I15: T02 | J15: Abstract; supplemental information | K15: =IF(C15="","",IF(IF(C15="","Add need ID",IF(NOT(SUMPRODUCT(--(NeedData[ID]=C15))=1),"Unknown or duplicate need",IF(INDEX(NeedData[Input check],MATCH(C15,NeedData[ID],0))<>"","Complete teaming need","")))<>"","",INDEX(NeedData[Priority],MATCH(C15,NeedData[ID],0)))) -> Required
A16: M31 | B16: C03 | C16: N01 | D16: Unresolved | E16: The inspected public records do not establish this capability for the proposed team. | F16: =IF(I16="","",IF(IF(I16="","Add source ID",IF(NOT(SUMPRODUCT(--(SourceData[ID]=I16))=1),"Unknown or duplicate source",IF(INDEX(SourceData[Input check],MATCH(I16,SourceData[ID],0))<>"","Complete source record","")))<>"","Check source",IF(INDEX(SourceData[URL],MATCH(I16,SourceData[ID],0))="",I16&IF(J16="",""," "&J16),HYPERLINK(INDEX(SourceData[URL],MATCH(I16,SourceData[ID],0)),I16&IF(J16="",""," "&J16))))) | G16: Provide the proposed airborne method, sensor and a relevant project. | H16: =IF(NOT(OR(A16<>"",B16<>"",C16<>"",D16<>"",E16<>"",G16<>"",I16<>"",J16<>"")),"",IF(A16="","Add ID",IF(NOT(SUMPRODUCT(--(MatchData[ID]=A16))=1),"Duplicate ID",IF(IF(B16="","Add candidate ID",IF(NOT(SUMPRODUCT(--(CandidateData[ID]=B16))=1),"Unknown or duplicate candidate",""))<>"",IF(B16="","Add candidate ID",IF(NOT(SUMPRODUCT(--(CandidateData[ID]=B16))=1),"Unknown or duplicate candidate","")),IF(IF(C16="","Add need ID",IF(NOT(SUMPRODUCT(--(NeedData[ID]=C16))=1),"Unknown or duplicate need",IF(INDEX(NeedData[Input check],MATCH(C16,NeedData[ID],0))<>"","Complete teaming need","")))<>"",IF(C16="","Add need ID",IF(NOT(SUMPRODUCT(--(NeedData[ID]=C16))=1),"Unknown or duplicate need",IF(INDEX(NeedData[Input check],MATCH(C16,NeedData[ID],0))<>"","Complete teaming need",""))),IF(SUMPRODUCT(--(MatchData[Candidate ID]=B16),--(MatchData[Need ID]=C16))<>1,"Duplicate candidate/need",IF(NOT(OR(D16="Pass",D16="Fail",D16="Unresolved")),"Choose status",IF(OR(E16="",G16=""),"Add assessment and next step",IF(AND(D16<>"Unresolved",I16=""),"Add evidence source",IF(I16="","",IF(I16="","Add source ID",IF(NOT(SUMPRODUCT(--(SourceData[ID]=I16))=1),"Unknown or duplicate source",IF(INDEX(SourceData[Input check],MATCH(I16,SourceData[ID],0))<>"","Complete source record",""))))))))))))) | K16: =IF(C16="","",IF(IF(C16="","Add need ID",IF(NOT(SUMPRODUCT(--(NeedData[ID]=C16))=1),"Unknown or duplicate need",IF(INDEX(NeedData[Input check],MATCH(C16,NeedData[ID],0))<>"","Complete teaming need","")))<>"","",INDEX(NeedData[Priority],MATCH(C16,NeedData[ID],0)))) -> Required
A17: M32 | B17: C03 | C17: N02 | D17: Pass | E17: Public award scope includes LiDAR and imagery. This supports relevant work scope, not compliance with every Bitter Lake specification. | F17: =IF(I17="","",IF(IF(I17="","Add source ID",IF(NOT(SUMPRODUCT(--(SourceData[ID]=I17))=1),"Unknown or duplicate source",IF(INDEX(SourceData[Input check],MATCH(I17,SourceData[ID],0))<>"","Complete source record","")))<>"","Check source",IF(INDEX(SourceData[URL],MATCH(I17,SourceData[ID],0))="",I17&IF(J17="",""," "&J17),HYPERLINK(INDEX(SourceData[URL],MATCH(I17,SourceData[ID],0)),I17&IF(J17="",""," "&J17))))) -> W03 Raw award description | G17: Confirm the specified point density, four-band imagery and proposed equipment. | H17: =IF(NOT(OR(A17<>"",B17<>"",C17<>"",D17<>"",E17<>"",G17<>"",I17<>"",J17<>"")),"",IF(A17="","Add ID",IF(NOT(SUMPRODUCT(--(MatchData[ID]=A17))=1),"Duplicate ID",IF(IF(B17="","Add candidate ID",IF(NOT(SUMPRODUCT(--(CandidateData[ID]=B17))=1),"Unknown or duplicate candidate",""))<>"",IF(B17="","Add candidate ID",IF(NOT(SUMPRODUCT(--(CandidateData[ID]=B17))=1),"Unknown or duplicate candidate","")),IF(IF(C17="","Add need ID",IF(NOT(SUMPRODUCT(--(NeedData[ID]=C17))=1),"Unknown or duplicate need",IF(INDEX(NeedData[Input check],MATCH(C17,NeedData[ID],0))<>"","Complete teaming need","")))<>"",IF(C17="","Add need ID",IF(NOT(SUMPRODUCT(--(NeedData[ID]=C17))=1),"Unknown or duplicate need",IF(INDEX(NeedData[Input check],MATCH(C17,NeedData[ID],0))<>"","Complete teaming need",""))),IF(SUMPRODUCT(--(MatchData[Candidate ID]=B17),--(MatchData[Need ID]=C17))<>1,"Duplicate candidate/need",IF(NOT(OR(D17="Pass",D17="Fail",D17="Unresolved")),"Choose status",IF(OR(E17="",G17=""),"Add assessment and next step",IF(AND(D17<>"Unresolved",I17=""),"Add evidence source",IF(I17="","",IF(I17="","Add source ID",IF(NOT(SUMPRODUCT(--(SourceData[ID]=I17))=1),"Unknown or duplicate source",IF(INDEX(SourceData[Input check],MATCH(I17,SourceData[ID],0))<>"","Complete source record",""))))))))))))) | I17: W03 | J17: Raw award description | K17: =IF(C17="","",IF(IF(C17="","Add need ID",IF(NOT(SUMPRODUCT(--(NeedData[ID]=C17))=1),"Unknown or duplicate need",IF(INDEX(NeedData[Input check],MATCH(C17,NeedData[ID],0))<>"","Complete teaming need","")))<>"","",INDEX(NeedData[Priority],MATCH(C17,NeedData[ID],0)))) -> Required
A18: M33 | B18: C03 | C18: N03 | D18: Unresolved | E18: The inspected public records do not establish this capability for the proposed team. | F18: =IF(I18="","",IF(IF(I18="","Add source ID",IF(NOT(SUMPRODUCT(--(SourceData[ID]=I18))=1),"Unknown or duplicate source",IF(INDEX(SourceData[Input check],MATCH(I18,SourceData[ID],0))<>"","Complete source record","")))<>"","Check source",IF(INDEX(SourceData[URL],MATCH(I18,SourceData[ID],0))="",I18&IF(J18="",""," "&J18),HYPERLINK(INDEX(SourceData[URL],MATCH(I18,SourceData[ID],0)),I18&IF(J18="",""," "&J18))))) | G18: Identify the field crew, New Mexico license holders and survey deliverables. | H18: =IF(NOT(OR(A18<>"",B18<>"",C18<>"",D18<>"",E18<>"",G18<>"",I18<>"",J18<>"")),"",IF(A18="","Add ID",IF(NOT(SUMPRODUCT(--(MatchData[ID]=A18))=1),"Duplicate ID",IF(IF(B18="","Add candidate ID",IF(NOT(SUMPRODUCT(--(CandidateData[ID]=B18))=1),"Unknown or duplicate candidate",""))<>"",IF(B18="","Add candidate ID",IF(NOT(SUMPRODUCT(--(CandidateData[ID]=B18))=1),"Unknown or duplicate candidate","")),IF(IF(C18="","Add need ID",IF(NOT(SUMPRODUCT(--(NeedData[ID]=C18))=1),"Unknown or duplicate need",IF(INDEX(NeedData[Input check],MATCH(C18,NeedData[ID],0))<>"","Complete teaming need","")))<>"",IF(C18="","Add need ID",IF(NOT(SUMPRODUCT(--(NeedData[ID]=C18))=1),"Unknown or duplicate need",IF(INDEX(NeedData[Input check],MATCH(C18,NeedData[ID],0))<>"","Complete teaming need",""))),IF(SUMPRODUCT(--(MatchData[Candidate ID]=B18),--(MatchData[Need ID]=C18))<>1,"Duplicate candidate/need",IF(NOT(OR(D18="Pass",D18="Fail",D18="Unresolved")),"Choose status",IF(OR(E18="",G18=""),"Add assessment and next step",IF(AND(D18<>"Unresolved",I18=""),"Add evidence source",IF(I18="","",IF(I18="","Add source ID",IF(NOT(SUMPRODUCT(--(SourceData[ID]=I18))=1),"Unknown or duplicate source",IF(INDEX(SourceData[Input check],MATCH(I18,SourceData[ID],0))<>"","Complete source record",""))))))))))))) | K18: =IF(C18="","",IF(IF(C18="","Add need ID",IF(NOT(SUMPRODUCT(--(NeedData[ID]=C18))=1),"Unknown or duplicate need",IF(INDEX(NeedData[Input check],MATCH(C18,NeedData[ID],0))<>"","Complete teaming need","")))<>"","",INDEX(NeedData[Priority],MATCH(C18,NeedData[ID],0)))) -> Required
A19: M34 | B19: C03 | C19: N04 | D19: Unresolved | E19: The inspected public records do not establish this capability for the proposed team. | F19: =IF(I19="","",IF(IF(I19="","Add source ID",IF(NOT(SUMPRODUCT(--(SourceData[ID]=I19))=1),"Unknown or duplicate source",IF(INDEX(SourceData[Input check],MATCH(I19,SourceData[ID],0))<>"","Complete source record","")))<>"","Check source",IF(INDEX(SourceData[URL],MATCH(I19,SourceData[ID],0))="",I19&IF(J19="",""," "&J19),HYPERLINK(INDEX(SourceData[URL],MATCH(I19,SourceData[ID],0)),I19&IF(J19="",""," "&J19))))) | G19: Provide a deliverable sample, QA approach and the responsible processing team. | H19: =IF(NOT(OR(A19<>"",B19<>"",C19<>"",D19<>"",E19<>"",G19<>"",I19<>"",J19<>"")),"",IF(A19="","Add ID",IF(NOT(SUMPRODUCT(--(MatchData[ID]=A19))=1),"Duplicate ID",IF(IF(B19="","Add candidate ID",IF(NOT(SUMPRODUCT(--(CandidateData[ID]=B19))=1),"Unknown or duplicate candidate",""))<>"",IF(B19="","Add candidate ID",IF(NOT(SUMPRODUCT(--(CandidateData[ID]=B19))=1),"Unknown or duplicate candidate","")),IF(IF(C19="","Add need ID",IF(NOT(SUMPRODUCT(--(NeedData[ID]=C19))=1),"Unknown or duplicate need",IF(INDEX(NeedData[Input check],MATCH(C19,NeedData[ID],0))<>"","Complete teaming need","")))<>"",IF(C19="","Add need ID",IF(NOT(SUMPRODUCT(--(NeedData[ID]=C19))=1),"Unknown or duplicate need",IF(INDEX(NeedData[Input check],MATCH(C19,NeedData[ID],0))<>"","Complete teaming need",""))),IF(SUMPRODUCT(--(MatchData[Candidate ID]=B19),--(MatchData[Need ID]=C19))<>1,"Duplicate candidate/need",IF(NOT(OR(D19="Pass",D19="Fail",D19="Unresolved")),"Choose status",IF(OR(E19="",G19=""),"Add assessment and next step",IF(AND(D19<>"Unresolved",I19=""),"Add evidence source",IF(I19="","",IF(I19="","Add source ID",IF(NOT(SUMPRODUCT(--(SourceData[ID]=I19))=1),"Unknown or duplicate source",IF(INDEX(SourceData[Input check],MATCH(I19,SourceData[ID],0))<>"","Complete source record",""))))))))))))) | K19: =IF(C19="","",IF(IF(C19="","Add need ID",IF(NOT(SUMPRODUCT(--(NeedData[ID]=C19))=1),"Unknown or duplicate need",IF(INDEX(NeedData[Input check],MATCH(C19,NeedData[ID],0))<>"","Complete teaming need","")))<>"","",INDEX(NeedData[Priority],MATCH(C19,NeedData[ID],0)))) -> Required
A20: M41 | B20: C04 | C20: N01 | D20: Unresolved | E20: The inspected public records do not establish this capability for the proposed team. | F20: =IF(I20="","",IF(IF(I20="","Add source ID",IF(NOT(SUMPRODUCT(--(SourceData[ID]=I20))=1),"Unknown or duplicate source",IF(INDEX(SourceData[Input check],MATCH(I20,SourceData[ID],0))<>"","Complete source record","")))<>"","Check source",IF(INDEX(SourceData[URL],MATCH(I20,SourceData[ID],0))="",I20&IF(J20="",""," "&J20),HYPERLINK(INDEX(SourceData[URL],MATCH(I20,SourceData[ID],0)),I20&IF(J20="",""," "&J20))))) | G20: Provide the proposed airborne method, sensor and a relevant project. | H20: =IF(NOT(OR(A20<>"",B20<>"",C20<>"",D20<>"",E20<>"",G20<>"",I20<>"",J20<>"")),"",IF(A20="","Add ID",IF(NOT(SUMPRODUCT(--(MatchData[ID]=A20))=1),"Duplicate ID",IF(IF(B20="","Add candidate ID",IF(NOT(SUMPRODUCT(--(CandidateData[ID]=B20))=1),"Unknown or duplicate candidate",""))<>"",IF(B20="","Add candidate ID",IF(NOT(SUMPRODUCT(--(CandidateData[ID]=B20))=1),"Unknown or duplicate candidate","")),IF(IF(C20="","Add need ID",IF(NOT(SUMPRODUCT(--(NeedData[ID]=C20))=1),"Unknown or duplicate need",IF(INDEX(NeedData[Input check],MATCH(C20,NeedData[ID],0))<>"","Complete teaming need","")))<>"",IF(C20="","Add need ID",IF(NOT(SUMPRODUCT(--(NeedData[ID]=C20))=1),"Unknown or duplicate need",IF(INDEX(NeedData[Input check],MATCH(C20,NeedData[ID],0))<>"","Complete teaming need",""))),IF(SUMPRODUCT(--(MatchData[Candidate ID]=B20),--(MatchData[Need ID]=C20))<>1,"Duplicate candidate/need",IF(NOT(OR(D20="Pass",D20="Fail",D20="Unresolved")),"Choose status",IF(OR(E20="",G20=""),"Add assessment and next step",IF(AND(D20<>"Unresolved",I20=""),"Add evidence source",IF(I20="","",IF(I20="","Add source ID",IF(NOT(SUMPRODUCT(--(SourceData[ID]=I20))=1),"Unknown or duplicate source",IF(INDEX(SourceData[Input check],MATCH(I20,SourceData[ID],0))<>"","Complete source record",""))))))))))))) | K20: =IF(C20="","",IF(IF(C20="","Add need ID",IF(NOT(SUMPRODUCT(--(NeedData[ID]=C20))=1),"Unknown or duplicate need",IF(INDEX(NeedData[Input check],MATCH(C20,NeedData[ID],0))<>"","Complete teaming need","")))<>"","",INDEX(NeedData[Priority],MATCH(C20,NeedData[ID],0)))) -> Required
A21: M42 | B21: C04 | C21: N02 | D21: Pass | E21: Public award scope includes LiDAR and imagery. This supports relevant work scope, not compliance with every Bitter Lake specification. | F21: =IF(I21="","",IF(IF(I21="","Add source ID",IF(NOT(SUMPRODUCT(--(SourceData[ID]=I21))=1),"Unknown or duplicate source",IF(INDEX(SourceData[Input check],MATCH(I21,SourceData[ID],0))<>"","Complete source record","")))<>"","Check source",IF(INDEX(SourceData[URL],MATCH(I21,SourceData[ID],0))="",I21&IF(J21="",""," "&J21),HYPERLINK(INDEX(SourceData[URL],MATCH(I21,SourceData[ID],0)),I21&IF(J21="",""," "&J21))))) -> W04 Raw award description | G21: Confirm the specified point density, four-band imagery and proposed equipment. | H21: =IF(NOT(OR(A21<>"",B21<>"",C21<>"",D21<>"",E21<>"",G21<>"",I21<>"",J21<>"")),"",IF(A21="","Add ID",IF(NOT(SUMPRODUCT(--(MatchData[ID]=A21))=1),"Duplicate ID",IF(IF(B21="","Add candidate ID",IF(NOT(SUMPRODUCT(--(CandidateData[ID]=B21))=1),"Unknown or duplicate candidate",""))<>"",IF(B21="","Add candidate ID",IF(NOT(SUMPRODUCT(--(CandidateData[ID]=B21))=1),"Unknown or duplicate candidate","")),IF(IF(C21="","Add need ID",IF(NOT(SUMPRODUCT(--(NeedData[ID]=C21))=1),"Unknown or duplicate need",IF(INDEX(NeedData[Input check],MATCH(C21,NeedData[ID],0))<>"","Complete teaming need","")))<>"",IF(C21="","Add need ID",IF(NOT(SUMPRODUCT(--(NeedData[ID]=C21))=1),"Unknown or duplicate need",IF(INDEX(NeedData[Input check],MATCH(C21,NeedData[ID],0))<>"","Complete teaming need",""))),IF(SUMPRODUCT(--(MatchData[Candidate ID]=B21),--(MatchData[Need ID]=C21))<>1,"Duplicate candidate/need",IF(NOT(OR(D21="Pass",D21="Fail",D21="Unresolved")),"Choose status",IF(OR(E21="",G21=""),"Add assessment and next step",IF(AND(D21<>"Unresolved",I21=""),"Add evidence source",IF(I21="","",IF(I21="","Add source ID",IF(NOT(SUMPRODUCT(--(SourceData[ID]=I21))=1),"Unknown or duplicate source",IF(INDEX(SourceData[Input check],MATCH(I21,SourceData[ID],0))<>"","Complete source record",""))))))))))))) | I21: W04 | J21: Raw award description | K21: =IF(C21="","",IF(IF(C21="","Add need ID",IF(NOT(SUMPRODUCT(--(NeedData[ID]=C21))=1),"Unknown or duplicate need",IF(INDEX(NeedData[Input check],MATCH(C21,NeedData[ID],0))<>"","Complete teaming need","")))<>"","",INDEX(NeedData[Priority],MATCH(C21,NeedData[ID],0)))) -> Required
